Workbook

Sheet Capital Gains Tax Calculator
A1: CAPITAL GAINS TAX CALCULATOR
A2: Estimated for planning purposes only - not tax, legal, or accounting advice.
B4: Initial Value | E4: Sale Value | H4: Length of Ownership
C5: 10000 | F5: 50000 | I5: More than a year
B7: Location (State) | E7: Annual Income | H7: Filing Status
C8: New Jersey | F8: 200000 | I8: Married Filing Jointly
B9: Tax Year
C10: 2025
B12: ADVANCED (optional - click the [+] in the row-number margin to expand)
B13: 401(k) Contribution | E13: IRA Contribution | H13: Itemized Deductions
C14: 0 | F14: 0 | I14: 0
B15: Number of Personal Exemptions (state only) | E15: Locality / City (optional)
C16: 0 | F16: None / Not Applicable
B18: =C63
A21: YOUR CAPITAL GAINS TAXES
B22: Tax Type | D22: Marginal Tax Rate | F22: Effective Tax Rate | H22: Tax Amount
B23: Federal | D23: =C64 | F23: =C65 | H23: =C56
B24: State | D24: =C66 | F24: =C67 | H24: =C61
B25: Local | D25: =C42 | F25: =C68 | H25: =C62
B26: Total Estimated Tax | H26: =C63
B28: Estimated for financial-planning purposes only. This calculator is not tax, legal, or accounting advice. Actual tax liability may differ based on individual circumstances, deductions, credits, tax elections, state/local rules, and other factors. Consult a qualified tax professional before making tax-related decisions. "Federal" includes the Net Investment Income Tax (3.8%) where applicable.
B32: Full calculation detail is available below for your advisor. Click the [+] in the row-number margin to expand.
A34: CALCULATION DETAIL (grouped - click + to expand)
B36: Standard Deduction (add-back for MAGI estimate) | C36: =INDEX('Tax Rates & Assumptions'!$D$28:$D$35,L42) | K36: Filing Status | L36: =I8
B37: Capital Loss Limit vs. Ordinary Income | C37: =INDEX('Tax Rates & Assumptions'!$D$39:$D$42,L41) | K37: Tax Year | L37: =C10
B38: NIIT Threshold | C38: =INDEX('Tax Rates & Assumptions'!$B$39:$B$42,L41) | K38: Federal Key | L38: =L37&"|"&L36
B39: NIIT Rate | C39: =INDEX('Tax Rates & Assumptions'!$C$39:$C$42,L41) | K39: Fed Bracket Row# | L39: =MATCH(L38,'Tax Rates & Assumptions'!$C$6:$C$13,0)
B40: State Standard Deduction | C40: =IF(L45="MFJ",INDEX('Tax Rates & Assumptions'!$E$46:$E$77,L48),INDEX('Tax Rates & Assumptions'!$D$46:$D$77,L48)) | K40: LTCG Bracket Row# | L40: =MATCH(L38,'Tax Rates & Assumptions'!$C$17:$C$24,0)
B41: Personal Exemption Amount (per exemption, state) | C41: =INDEX('Tax Rates & Assumptions'!$C$164:$C$164,1) | K41: Status Row# (NIIT/CapLoss) | L41: =MATCH(L36,'Tax Rates & Assumptions'!$A$39:$A$42,0)
B42: Local Tax Rate | C42: =IF(L50=0,0,INDEX('Tax Rates & Assumptions'!$D$148:$D$161,L50)) | K42: StdDed Row# | L42: =MATCH(L38,'Tax Rates & Assumptions'!$C$28:$C$35,0)
B43: Capital Gain / (Loss) on Sale | C43: =(F5-C5) | K43: State Name | L43: =C8
B44: Is Long-Term? | C44: =IF(I5="More than a year",1,0) | K44: State Code | L44: =INDEX('Tax Rates & Assumptions'!$A$46:$A$77,MATCH(L43,'Tax Rates & Assumptions'!$B$46:$B$77,0))
B45: Ordinary-Taxed Portion (short-term gain, or loss deduction capped) | C45: =IF(C43>=0,IF(C44=1,0,C43),MAX(C43,-C37)) | K45: State Category | L45: =IF(L36="Married Filing Jointly","MFJ","Single")
B46: Preferential-Rate Portion (long-term gain) | C46: =IF(C43>=0,IF(C44=1,C43,0),0) | K46: State Key | L46: =L44&"|"&L45
B47: Taxable Income Before the Gain | C47: =MAX(0,F8-C14-F14-MAX(I14,INDEX('Tax Rates & Assumptions'!$D$28:$D$35,L42))) | K47: State Bracket Row# | L47: =MATCH(L46,'Tax Rates & Assumptions'!$C$81:$C$144,0)
B48: Taxable Income Including the Gain | C48: =MAX(0,C47+C45) | K48: State Master Row# | L48: =MATCH(L44,'Tax Rates & Assumptions'!$A$46:$A$77,0)
B49: Federal Tax on Income Alone (no gain) | C49: =SUMPRODUCT((C47>$M$53:$M$59)*($L$53:$L$59)*(MIN(C47,$N$53:$N$59)-$M$53:$M$59)) | K49: Locality Name | L49: =F16
B50: Federal Tax on Income Including the Gain | C50: =SUMPRODUCT((C48>$M$53:$M$59)*($L$53:$L$59)*(MIN(C48,$N$53:$N$59)-$M$53:$M$59)) | K50: Locality Row# | L50: =IFERROR(MATCH(L49,'Tax Rates & Assumptions'!$B$148:$B$161,0),0)
B51: Federal Tax on Ordinary Portion of the Gain | C51: =C50-C49
B52: Federal Tax on Preferential (Long-Term) Portion (stacked) | C52: =SUMPRODUCT($L$62:$L$64*(MAX(0,MIN((C48+C46),$N$62:$N$64)-MAX(C48,$M$62:$M$64)))) | K52: Federal Ordinary Brackets
...

Sheet Tax Rates & Assumptions
A1: TAX RATES & ASSUMPTIONS
A2: This tab stores every tax-law figure used by the Capital Gains Tax Estimator (federal brackets, deduction amounts, thresholds, and state rates), organized by tax year. Update it to refresh figures for a new tax year or a state not yet listed - no formulas on the calculator tab need to change.
A4: Federal Ordinary Income Tax Brackets
A5: Year | B5: Filing Status | C5: Key | D5: Rate 1 | E5: Min 1 | F5: Max 1 | G5: Rate 2 | H5: Min 2 | I5: Max 2 | J5: Rate 3 | K5: Min 3 | L5: Max 3 | M5: Rate 4 | N5: Min 4 | O5: Max 4 | P5: Rate 5 | Q5: Min 5 | R5: Max 5 | S5: Rate 6 | T5: Min 6 | U5: Max 6 | V5: Rate 7 | W5: Min 7 | X5: Max 7
A6: 2024 | B6: Single | C6: =A6&"|"&B6 | D6: 0.1 | E6: 0 | F6: =H6 | G6: 0.12 | H6: 11600 | I6: =K6 | J6: 0.22 | K6: 47150 | L6: =N6 | M6: 0.24 | N6: 100525 | O6: =Q6 | P6: 0.32 | Q6: 191950 | R6: =T6 | S6: 0.35 | T6: 243725 | U6: =W6 | V6: 0.37 | W6: 609350 | X6: 999999999
A7: 2024 | B7: Married Filing Jointly | C7: =A7&"|"&B7 | D7: 0.1 | E7: 0 | F7: =H7 | G7: 0.12 | H7: 23200 | I7: =K7 | J7: 0.22 | K7: 94300 | L7: =N7 | M7: 0.24 | N7: 201050 | O7: =Q7 | P7: 0.32 | Q7: 383900 | R7: =T7 | S7: 0.35 | T7: 487450 | U7: =W7 | V7: 0.37 | W7: 731200 | X7: 999999999
A8: 2024 | B8: Married Filing Separately | C8: =A8&"|"&B8 | D8: 0.1 | E8: 0 | F8: =H8 | G8: 0.12 | H8: 11600 | I8: =K8 | J8: 0.22 | K8: 47150 | L8: =N8 | M8: 0.24 | N8: 100525 | O8: =Q8 | P8: 0.32 | Q8: 191950 | R8: =T8 | S8: 0.35 | T8: 243725 | U8: =W8 | V8: 0.37 | W8: 365600 | X8: 999999999
A9: 2024 | B9: Head of Household | C9: =A9&"|"&B9 | D9: 0.1 | E9: 0 | F9: =H9 | G9: 0.12 | H9: 16550 | I9: =K9 | J9: 0.22 | K9: 63100 | L9: =N9 | M9: 0.24 | N9: 100500 | O9: =Q9 | P9: 0.32 | Q9: 191950 | R9: =T9 | S9: 0.35 | T9: 243700 | U9: =W9 | V9: 0.37 | W9: 609350 | X9: 999999999
A10: 2025 | B10: Single | C10: =A10&"|"&B10 | D10: 0.1 | E10: 0 | F10: =H10 | G10: 0.12 | H10: 11925 | I10: =K10 | J10: 0.22 | K10: 48475 | L10: =N10 | M10: 0.24 | N10: 103350 | O10: =Q10 | P10: 0.32 | Q10: 197300 | R10: =T10 | S10: 0.35 | T10: 250525 | U10: =W10 | V10: 0.37 | W10: 626350 | X10: 999999999
A11: 2025 | B11: Married Filing Jointly | C11: =A11&"|"&B11 | D11: 0.1 | E11: 0 | F11: =H11 | G11: 0.12 | H11: 23850 | I11: =K11 | J11: 0.22 | K11: 96950 | L11: =N11 | M11: 0.24 | N11: 206700 | O11: =Q11 | P11: 0.32 | Q11: 394600 | R11: =T11 | S11: 0.35 | T11: 501050 | U11: =W11 | V11: 0.37 | W11: 751600 | X11: 999999999
A12: 2025 | B12: Married Filing Separately | C12: =A12&"|"&B12 | D12: 0.1 | E12: 0 | F12: =H12 | G12: 0.12 | H12: 11925 | I12: =K12 | J12: 0.22 | K12: 48475 | L12: =N12 | M12: 0.24 | N12: 103350 | O12: =Q12 | P12: 0.32 | Q12: 197300 | R12: =T12 | S12: 0.35 | T12: 250525 | U12: =W12 | V12: 0.37 | W12: 375800 | X12: 999999999
A13: 2025 | B13: Head of Household | C13: =A13&"|"&B13 | D13: 0.1 | E13: 0 | F13: =H13 | G13: 0.12 | H13: 17000 | I13: =K13 | J13: 0.22 | K13: 64850 | L13: =N13 | M13: 0.24 | N13: 103350 | O13: =Q13 | P13: 0.32 | Q13: 197300 | R13: =T13 | S13: 0.35 | T13: 250500 | U13: =W13 | V13: 0.37 | W13: 626350 | X13: 999999999
A15: Long-Term Capital Gains Brackets (0% / 15% / 20%)
A16: Year | B16: Filing Status | C16: Key | D16: Rate 1 | E16: Min 1 | F16: Max 1 | G16: Rate 2 | H16: Min 2 | I16: Max 2 | J16: Rate 3 | K16: Min 3 | L16: Max 3
A17: 2024 | B17: Single | C17: =A17&"|"&B17 | D17: 0 | E17: 0 | F17: =H17 | G17: 0.15 | H17: 47025 | I17: =K17 | J17: 0.2 | K17: 518900 | L17: 999999999
A18: 2024 | B18: Married Filing Jointly | C18: =A18&"|"&B18 | D18: 0 | E18: 0 | F18: =H18 | G18: 0.15 | H18: 94050 | I18: =K18 | J18: 0.2 | K18: 583750 | L18: 999999999
A19: 2024 | B19: Married Filing Separately | C19: =A19&"|"&B19 | D19: 0 | E19: 0 | F19: =H19 | G19: 0.15 | H19: 47025 | I19: =K19 | J19: 0.2 | K19: 291850 | L19: 999999999
A20: 2024 | B20: Head of Household | C20: =A20&"|"&B20 | D20: 0 | E20: 0 | F20: =H20 | G20: 0.15 | H20: 63000 | I20: =K20 | J20: 0.2 | K20: 551350 | L20: 999999999
A21: 2025 | B21: Single | C21: =A21&"|"&B21 | D21: 0 | E21: 0 | F21: =H21 | G21: 0.15 | H21: 48350 | I21: =K21 | J21: 0.2 | K21: 533400 | L21: 999999999
A22: 2025 | B22: Married Filing Jointly | C22: =A22&"|"&B22 | D22: 0 | E22: 0 | F22: =H22 | G22: 0.15 | H22: 96700 | I22: =K22 | J22: 0.2 | K22: 600050 | L22: 999999999
A23: 2025 | B23: Married Filing Separately | C23: =A23&"|"&B23 | D23: 0 | E23: 0 | F23: =H23 | G23: 0.15 | H23: 48350 | I23: =K23 | J23: 0.2 | K23: 300000 | L23: 999999999
A24: 2025 | B24: Head of Household | C24: =A24&"|"&B24 | D24: 0 | E24: 0 | F24: =H24 | G24: 0.15 | H24: 64750 | I24: =K24 | J24: 0.2 | K24: 566700 | L24: 999999999
A26: Standard Deduction
A27: Year | B27: Filing Status | C27: Key | D27: Standard Deduction
A28: 2024 | B28: Single | C28: =A28&"|"&B28 | D28: 14600
A29: 2024 | B29: Married Filing Jointly | C29: =A29&"|"&B29 | D29: 29200
A30: 2024 | B30: Married Filing Separately | C30: =A30&"|"&B30 | D30: 14600
A31: 2024 | B31: Head of Household | C31: =A31&"|"&B31 | D31: 21900
A32: 2025 | B32: Single | C32: =A32&"|"&B32 | D32: 15000
A33: 2025 | B33: Married Filing Jointly | C33: =A33&"|"&B33 | D33: 30000
A34: 2025 | B34: Married Filing Separately | C34: =A34&"|"&B34 | D34: 15000
A35: 2025 | B35: Head of Household | C35: =A35&"|"&B35 | D35: 22500
A37: NIIT Thresholds & Capital-Loss Deduction Limit (fixed by statute)
A38: Filing Status | B38: NIIT MAGI Threshold | C38: NIIT Rate | D38: Annual Capital-Loss Deduction Limit
A39: Single | B39: 200000 | C39: 0.038 | D39: 3000
A40: Married Filing Jointly | B40: 250000 | C40: 0.038 | D40: 3000
A41: Married Filing Separately | B41: 125000 | C41: 0.038 | D41: 1500
A42: Head of Household | B42: 200000 | C42: 0.038 | D42: 3000
A44: State Master List & Capital-Gains Treatment
A45: State Code | B45: State Name | C45: Tax Type | D45: Std. Deduction (Single) | E45: Std. Deduction (MFJ) | F45: Capital-Gains Treatment | G45: Notes / Simplifications
...
