Workbook

Sheet Div & Interest Tax Calculator
A1: DIVIDEND & INTEREST INCOME TAX CALCULATOR
A2: Estimated federal and state tax on dividends (qualified and non-qualified) and interest income (taxable, U.S. Treasury, and tax-exempt municipal) -- for financial-planning discussion purposes only. This is not tax, legal, or accounting advice. For realized gains/losses, see the companion Capital Gains Tax Estimator.
A4: CLIENT INPUTS (enter only the fields that apply)
B5: Tax Year | E5: Filing Status | H5: State of Residence
C6: 2025 | F6: Married Filing Jointly | I6: New Jersey
B7: Total Household Income (wages/salary; excludes the portfolio income below) | E7: Pre-Tax Deductions (401(k), HSA, etc.) | H7: Non-Qualified (Ordinary) Dividends
C8: 200000 | F8: 10000 | I8: 5000
B9: Qualified Dividends | E9: Taxable Interest (bank, CDs, corporate bonds, etc.) | H9: U.S. Treasury / Government Interest
C10: 15000 | F10: 8000 | I10: 4000
B11: Tax-Exempt Municipal Bond Interest -- issued by your state of residence | E11: Tax-Exempt Municipal Bond Interest -- issued by other states
C12: 0 | F12: 0
A14: PORTFOLIO INCOME
B15: Total Household Income | G15: =C8 -> 200000
B16: Pre-Tax Deductions | G16: =F8 -> 10000
B17: Standard Deduction (auto, based on tax year & filing status) | G17: =L65 -> 30000
B18: Estimated Taxable Income Before Portfolio Income | G18: =L99 -> 160000
B19: Non-Qualified (Ordinary) Dividends | G19: =I8 -> 5000
B20: Qualified Dividends | G20: =C10 -> 15000
B21: Taxable Interest (incl. U.S. Treasury) | G21: =(F10+I10) -> 12000
B22: Tax-Exempt Municipal Bond Interest (informational; not federally taxed) | G22: =(C12+F12) -> 0
B23: Total Taxable Portfolio Income -- Overall | G23: =L121 -> 32000
A25: ESTIMATED FEDERAL TAX
B26: Tax on Non-Qualified Dividends & Interest (ordinary rates) | G26: =L104 -> 3740
B27: Tax on Qualified Dividends (0% / 15% / 20%, stacked) | G27: =L107 -> 2250
B28: Net Investment Income Tax (NIIT, 3.8%, when applicable) | G28: =L110 -> 0
B29: Total Estimated Federal Tax | G29: =L111 -> 5990
A31: ESTIMATED STATE TAX
B32: State | G32: =I6 -> New Jersey
B33: State Tax Treatment | G33: =L74 -> Progressive brackets (taxed as ordinary income)
B34: Estimated State Tax on Portfolio Income | G34: =L119 -> 1783.6
A36: TOTAL
B37: Total Estimated Tax on Portfolio Income (Federal + State) | G37: =L120 -> 7773.6
B38: Effective Tax Rate on Portfolio Income | G38: =L122 -> 0.242925
B39: Estimated After-Tax Portfolio Income | G39: =L123 -> 24226.4
A41: DISCLAIMER: This calculator produces a planning-level ESTIMATE only. It is not tax, legal, or accounting advice and should not be relied upon to prepare an actual tax return. It does not account for every individual tax situation -- among other things, it does not model AMT (including the municipal-bond private-activity-bond preference item), tax credits, itemized deductions, self-employment or additional Medicare tax, the taxation of Social Security benefits, ACA premium tax credit MAGI effects, or local/municipal income taxes (other than where noted). U.S. Treasury interest is assumed exempt from state tax in every state (a federal-law requirement); in-state municipal bond interest is assumed state-exempt and out-of-state municipal bond interest is assumed state-taxable -- a small number of states may vary from this general rule. State figures are simplified and some bracket thresholds are approximate -- see the notes column on the 'Tax Rates & Assumptions' tab for each state's specific assumptions, and verify current-year figures before precise client use. This tool does not cover realized capital gains or losses -- see the companion Capital Gains Tax Estimator for that. Always consult a qualified tax professional before making decisions based on this estimate. To update for a future tax year, edit the brackets and thresholds on the 'Tax Rates & Assumptions' tab -- no formulas on this tab need to change.
K54: CALCULATION DETAIL (reference only -- expand the outline to the left to audit the formulas behind every figure above)
K55: Filing category (Single/MFJ) | L55: =IF(F6="Married Filing Jointly","MFJ","Single") -> MFJ
K56: Federal key | L56: =C6&"|"&L55 -> 2025|MFJ
K57: Federal ordinary bracket row# | L57: =MATCH(L56,'Tax Rates & Assumptions'!C$6:C$1006,0) -> 4
K58: Qualified-dividend (LTCG-rate) bracket row# | L58: =MATCH(L56,'Tax Rates & Assumptions'!C$13:C$1013,0) -> 4
...

Sheet Tax Rates & Assumptions
A1: TAX RATES & ASSUMPTIONS
A2: This tab stores every tax-law figure used by the Dividend & Interest Income Tax Calculator (federal brackets, deduction amounts, thresholds, and all 50-state + DC treatment), organized by tax year. Update it to refresh figures for a new tax year -- no formulas on the Calculator tab need to change. Cells with a Notes column document simplifications/assumptions; verify flagged figures before precise client use.
A4: Federal Ordinary Income Tax Brackets
A5: Year | B5: Filing Status | C5: Key | D5: Rate 1 | E5: Min 1 | F5: Max 1 | G5: Rate 2 | H5: Min 2 | I5: Max 2 | J5: Rate 3 | K5: Min 3 | L5: Max 3 | M5: Rate 4 | N5: Min 4 | O5: Max 4 | P5: Rate 5 | Q5: Min 5 | R5: Max 5 | S5: Rate 6 | T5: Min 6 | U5: Max 6 | V5: Rate 7 | W5: Min 7 | X5: Max 7
A6: 2024 | B6: Single | C6: =A6&"|"&B6 -> 2024|Single | D6: 0.1 | E6: 0 | F6: =H6 -> 11600 | G6: 0.12 | H6: 11600 | I6: =K6 -> 47150 | J6: 0.22 | K6: 47150 | L6: =N6 -> 100525 | M6: 0.24 | N6: 100525 | O6: =Q6 -> 191950 | P6: 0.32 | Q6: 191950 | R6: =T6 -> 243725 | S6: 0.35 | T6: 243725 | U6: =W6 -> 609350 | V6: 0.37 | W6: 609350 | X6: 999999999
A7: 2024 | B7: MFJ | C7: =A7&"|"&B7 -> 2024|MFJ | D7: 0.1 | E7: 0 | F7: =H7 -> 23200 | G7: 0.12 | H7: 23200 | I7: =K7 -> 94300 | J7: 0.22 | K7: 94300 | L7: =N7 -> 201050 | M7: 0.24 | N7: 201050 | O7: =Q7 -> 383900 | P7: 0.32 | Q7: 383900 | R7: =T7 -> 487450 | S7: 0.35 | T7: 487450 | U7: =W7 -> 731200 | V7: 0.37 | W7: 731200 | X7: 999999999
A8: 2025 | B8: Single | C8: =A8&"|"&B8 -> 2025|Single | D8: 0.1 | E8: 0 | F8: =H8 -> 11925 | G8: 0.12 | H8: 11925 | I8: =K8 -> 48475 | J8: 0.22 | K8: 48475 | L8: =N8 -> 103350 | M8: 0.24 | N8: 103350 | O8: =Q8 -> 197300 | P8: 0.32 | Q8: 197300 | R8: =T8 -> 250525 | S8: 0.35 | T8: 250525 | U8: =W8 -> 626350 | V8: 0.37 | W8: 626350 | X8: 999999999
A9: 2025 | B9: MFJ | C9: =A9&"|"&B9 -> 2025|MFJ | D9: 0.1 | E9: 0 | F9: =H9 -> 23850 | G9: 0.12 | H9: 23850 | I9: =K9 -> 96950 | J9: 0.22 | K9: 96950 | L9: =N9 -> 206700 | M9: 0.24 | N9: 206700 | O9: =Q9 -> 394600 | P9: 0.32 | Q9: 394600 | R9: =T9 -> 501050 | S9: 0.35 | T9: 501050 | U9: =W9 -> 751600 | V9: 0.37 | W9: 751600 | X9: 999999999
A11: Federal Qualified Dividend / LTCG-Rate Brackets (0% / 15% / 20%)
A12: Year | B12: Filing Status | C12: Key | D12: Rate 1 | E12: Min 1 | F12: Max 1 | G12: Rate 2 | H12: Min 2 | I12: Max 2 | J12: Rate 3 | K12: Min 3 | L12: Max 3
A13: 2024 | B13: Single | C13: =A13&"|"&B13 -> 2024|Single | D13: 0 | E13: 0 | F13: =H13 -> 47025 | G13: 0.15 | H13: 47025 | I13: =K13 -> 518900 | J13: 0.2 | K13: 518900 | L13: 999999999
A14: 2024 | B14: MFJ | C14: =A14&"|"&B14 -> 2024|MFJ | D14: 0 | E14: 0 | F14: =H14 -> 94050 | G14: 0.15 | H14: 94050 | I14: =K14 -> 583750 | J14: 0.2 | K14: 583750 | L14: 999999999
A15: 2025 | B15: Single | C15: =A15&"|"&B15 -> 2025|Single | D15: 0 | E15: 0 | F15: =H15 -> 48350 | G15: 0.15 | H15: 48350 | I15: =K15 -> 533400 | J15: 0.2 | K15: 533400 | L15: 999999999
A16: 2025 | B16: MFJ | C16: =A16&"|"&B16 -> 2025|MFJ | D16: 0 | E16: 0 | F16: =H16 -> 96700 | G16: 0.15 | H16: 96700 | I16: =K16 -> 600050 | J16: 0.2 | K16: 600050 | L16: 999999999
A18: Federal Standard Deduction
A19: Year | B19: Filing Status | C19: Key | D19: Standard Deduction
A20: 2024 | B20: Single | C20: =A20&"|"&B20 -> 2024|Single | D20: 14600
A21: 2024 | B21: MFJ | C21: =A21&"|"&B21 -> 2024|MFJ | D21: 29200
A22: 2025 | B22: Single | C22: =A22&"|"&B22 -> 2025|Single | D22: 15000
A23: 2025 | B23: MFJ | C23: =A23&"|"&B23 -> 2025|MFJ | D23: 30000
A25: NIIT Thresholds & Rate (fixed by statute)
A26: Filing Status | B26: NIIT MAGI Threshold | C26: NIIT Rate
A27: Single | B27: 200000 | C27: 0.038
A28: MFJ | B28: 250000 | C28: 0.038
A31: State Master List & Interest/Dividend Tax Treatment (all 50 states + DC)
A32: State Code | B32: State Name | C32: Tax Type | D32: Flat Rate | E32: Special Mechanism | F32: Special Param 1 | G32: Special Param 2 | H32: Special Param 3 | I32: Special Param 4 | J32: Std. Deduction (Single) | K32: Std. Deduction (MFJ) | L32: Client-Facing Description | M32: Notes / Assumptions / Vintage
A33: AL | B33: Alabama | C33: Bracket | D33: 0 | F33: 0 | G33: 0 | H33: 0 | I33: 0 | J33: 0 | K33: 0 | L33: Progressive brackets (taxed as ordinary income) | M33: Graduated brackets, but thresholds are so low most filers effectively pay the 5% top rate.
A34: AK | B34: Alaska | C34: None | D34: 0 | F34: 0 | G34: 0 | H34: 0 | I34: 0 | J34: 0 | K34: 0 | L34: No state income tax | M34: No individual income tax; interest and dividends are not taxed.
A35: AZ | B35: Arizona | C35: Flat | D35: 0.025 | F35: 0 | G35: 0 | H35: 0 | I35: 0 | J35: 14600 | K35: 29200 | L35: Flat 2.50% | M35: Flat-rate state; 2.50% applies to all taxable income including interest and dividends. 2025 rate.
A36: AR | B36: Arkansas | C36: Bracket | D36: 0 | F36: 0 | G36: 0 | H36: 0 | I36: 0 | J36: 0 | K36: 0 | L36: Progressive brackets (taxed as ordinary income) | M36: Graduated brackets (same schedule for all filing statuses; simplified/approximate). (Arkansas's 50% capital-gains exclusion does not apply to interest or dividends.)
A37: CA | B37: California | C37: Bracket | D37: 0 | F37: 0 | G37: 0 | H37: 0 | I37: 0 | J37: 5540 | K37: 11080 | L37: Progressive brackets (taxed as ordinary income) | M37: Progressive brackets; includes the 1% Mental Health Services surcharge on income over $1,000,000.
A38: CO | B38: Colorado | C38: Flat | D38: 0.0425 | F38: 0 | G38: 0 | H38: 0 | I38: 0 | J38: 0 | K38: 0 | L38: Flat 4.25% | M38: Flat-rate state; 4.25% applies to all taxable income including interest and dividends. 2025 rate.
A39: CT | B39: Connecticut | C39: Bracket | D39: 0 | F39: 0 | G39: 0 | H39: 0 | I39: 0 | J39: 0 | K39: 0 | L39: Progressive brackets (taxed as ordinary income) | M39: Progressive brackets. Connecticut's benefit-recapture provision for high earners is not modeled.
A40: DE | B40: Delaware | C40: Bracket | D40: 0 | F40: 0 | G40: 0 | H40: 0 | I40: 0 | J40: 0 | K40: 0 | L40: Progressive brackets (taxed as ordinary income) | M40: Progressive brackets (same schedule for all filing statuses).
A41: DC | B41: District of Columbia | C41: Bracket | D41: 0 | F41: 0 | G41: 0 | H41: 0 | I41: 0 | J41: 14600 | K41: 29200 | L41: Progressive brackets (taxed as ordinary income) | M41: Progressive brackets (same schedule for all filing statuses).
A42: FL | B42: Florida | C42: None | D42: 0 | F42: 0 | G42: 0 | H42: 0 | I42: 0 | J42: 0 | K42: 0 | L42: No state income tax | M42: No individual income tax; interest and dividends are not taxed.
A43: GA | B43: Georgia | C43: Flat | D43: 0.0519 | F43: 0 | G43: 0 | H43: 0 | I43: 0 | J43: 12000 | K43: 24000 | L43: Flat 5.19% | M43: Flat-rate state; 5.19% applies to all taxable income including interest and dividends. 2025 rate.
A44: HI | B44: Hawaii | C44: Bracket | D44: 0 | F44: 0 | G44: 0 | H44: 0 | I44: 0 | J44: 2200 | K44: 4400 | L44: Progressive brackets (taxed as ordinary income) | M44: Progressive brackets up to 11%. (Hawaii's 7.25% preferential rate applies only to long-term capital gains, not to interest or dividends.) Middle bracket thresholds are approximate -- verify against HI DOTAX.
... A53: MD | B53: Maryland | C53: Bracket | D53: 0 | F53: 0 | G53: 0 | H53: 0 | I53: 0 | J53: 2400 | K53: 4850 | L53: Progressive brackets (taxed as ordinary income) | M53: Progressive brackets (includes the 6.25%/6.5% top brackets added for 2025). Excludes county/city 'piggyback' local income tax (2.25%-3.20%) -- actual total MD tax will be higher than shown.
A54: MA | B54: Massachusetts | C54: Special | D54: 0 | E54: MA_FLAT | F54: 0.05 | G54: 1083150 | H54: 0.04 | I54: 0 | J54: 0 | K54: 0 | L54: Flat 5% (plus 4% surtax over $1,083,150) -- no qualified-dividend preference | M54: Flat tax. Massachusetts does NOT give qualified dividends any preferential rate -- all interest and dividends (qualified or not) are taxed at a flat 5%, plus a 4% surtax on all income above $1,083,150 (2025).
...
