Workbook

Sheet By Participant
A1: Participant Balances Report - Trident Abstract (09-20-26)
A2: Market value by participant; only funds with a balance are listed.
A4: Participant | B4: Status | C4: Fund | D4: Balance | E4: Participant Total
A5: ACCOUNT, FORFEITURE | B5: A-ACTIVE | C5: OV6J-AS TREA PL MMKT SVC | D5: 1283.97 | E5: =SUM(D5:D5) -> 1283.97
A6: ACCOUNT, RCP | B6: A-ACTIVE | C6: OV6J-AS TREA PL MMKT SVC | D6: 1.63 | E6: =SUM(D6:D6) -> 1.63
A7: BAKER, CHARLES | B7: T-TERMINATED | C7: 3005-FA FREEDOM 2015 K6 | D7: 291.83668 | E7: =SUM(D7:D7) -> 291.83668
A8: BETZ, LISA | B8: A-ACTIVE | C8: 2328-FID 500 INDEX | D8: 97614.091 | E8: =SUM(D8:D13) -> 178110.41
C9: 2352-FID MID CAP IDX | D9: 17256.065
C10: OEM4-JPMORGAN INCOME R6 | D10: 13307.687
C11: OQTF-HARBOR SCG INST | D11: 15904.985
C12: OUBE-AF EUPAC FUND R6 | D12: 17055.215
C13: OUFP-AF NEW WORLD R6 | D13: 16972.363
A14: BOUFORD, LAURIE | B14: T-TERMINATED | C14: 3008-FA FREEDOM 2030 K6 | D14: 532.0123 | E14: =SUM(D14:D14) -> 532.0123
A15: CALLAHAN, TAYLOR | B15: A-ACTIVE | C15: 3014-FA FREEDOM 2060 K6 | D15: 49487.259 | E15: =SUM(D15:D15) -> 49487.259
A16: CARTON, ANDREW P | B16: A-ACTIVE | C16: 3007-FA FREEDOM 2025 K6 | D16: 133490.9 | E16: =SUM(D16:D18) -> 767978.96
C17: 3015-FA FREEDOM RETIRE K6 | D17: 113825.86
C18: OV6J-AS TREA PL MMKT SVC | D18: 520662.2
A19: CARTON, CHRISTOPHER M | B19: A-ACTIVE | C19: 3008-FA FREEDOM 2030 K6 | D19: 1422238.4 | E19: =SUM(D19:D19) -> 1422238.4
A20: CARTON, KATHLEEN | B20: A-ACTIVE | C20: 3008-FA FREEDOM 2030 K6 | D20: 371297.42 | E20: =SUM(D20:D20) -> 371297.42
A21: CARTON, RACHEL | B21: A-ACTIVE | C21: 3014-FA FREEDOM 2060 K6 | D21: 35305.41 | E21: =SUM(D21:D21) -> 35305.41
A22: CASLER, SANDRA J | B22: R-RETIRED | C22: 3005-FA FREEDOM 2015 K6 | D22: 68333.247 | E22: =SUM(D22:D22) -> 68333.247
A23: CAVAZZONI, TINA | B23: A-ACTIVE | C23: 3010-FA FREEDOM 2040 K6 | D23: 10648.245 | E23: =SUM(D23:D23) -> 10648.245
A24: CONFORTI, JOHN N | B24: A-ACTIVE | C24: 3008-FA FREEDOM 2030 K6 | D24: 798248.21 | E24: =SUM(D24:D24) -> 798248.21
A25: CONWAY, CHRISTOPHER W | B25: A-ACTIVE | C25: OV6J-AS TREA PL MMKT SVC | D25: 61706.2 | E25: =SUM(D25:D25) -> 61706.2
A26: COSTA, JENNIFER A | B26: A-ACTIVE | C26: 2328-FID 500 INDEX | D26: 134068.11 | E26: =SUM(D26:D26) -> 134068.11
A27: COSTELLO, HEATHER | B27: A-ACTIVE | C27: 3010-FA FREEDOM 2040 K6 | D27: 20590.63 | E27: =SUM(D27:D27) -> 20590.63
A28: DEROGATIS, ROSAMARIE | B28: T-TERMINATED | C28: 3005-FA FREEDOM 2015 K6 | D28: 92092.342 | E28: =SUM(D28:D28) -> 92092.342
A29: DICECILIA, LISA | B29: E-ELIGIBLE | C29: 3007-FA FREEDOM 2025 K6 | D29: 1823.8927 | E29: =SUM(D29:D29) -> 1823.8927
A30: DIMAGGIO, GINA | B30: A-ACTIVE | C30: 3008-FA FREEDOM 2030 K6 | D30: 158925.97 | E30: =SUM(D30:D30) -> 158925.97
A31: FURRULE, LISA | B31: A-ACTIVE | C31: 3008-FA FREEDOM 2030 K6 | D31: 4225.5353 | E31: =SUM(D31:D31) -> 4225.5353
A32: GARCIA, PAULA | B32: T-TERMINATED | C32: 3010-FA FREEDOM 2040 K6 | D32: 4269.8065 | E32: =SUM(D32:D33) -> 14935.701
C33: OYQA-JPM LG CAP GROWTH R6 | D33: 10665.895
A34: GASSARO, KOREN E | B34: A-ACTIVE | C34: 3010-FA FREEDOM 2040 K6 | D34: 108163.4 | E34: =SUM(D34:D34) -> 108163.4
A35: GAWRON, JOSEPH W | B35: A-ACTIVE | C35: 2352-FID MID CAP IDX | D35: 69571.396 | E35: =SUM(D35:D37) -> 595347.89
C36: 3010-FA FREEDOM 2040 K6 | D36: 398061.47
C37: OIWD-BLKRK EQUITY DIV K | D37: 127715.02
A38: GRABAS, JOSEPH | B38: A-ACTIVE | C38: 3007-FA FREEDOM 2025 K6 | D38: 30102.663 | E38: =SUM(D38:D39) -> 113928.87
C39: 3011-FA FREEDOM 2045 K6 | D39: 83826.209
A40: GRABAS, PATRICIA | B40: A-ACTIVE | C40: 3007-FA FREEDOM 2025 K6 | D40: 55974.71 | E40: =SUM(D40:D40) -> 55974.71
A41: GUTMAN, NANCY A | B41: A-ACTIVE | C41: 3006-FA FREEDOM 2020 K6 | D41: 234827.8 | E41: =SUM(D41:D41) -> 234827.8
...

Sheet Fund Summary
A1: Fund Summary - Trident Abstract (09-20-26)
A3: Fund | B3: # Participants | C3: Total Balance | D3: % of Plan
A4: 2328-FID 500 INDEX | B4: =COUNTIF('By Participant'!$C$5:$C$57,A4) -> 2 | C4: =SUMIF('By Participant'!$C$5:$C$57,A4,'By Participant'!$D$5:$D$57) -> 231682.2 | D4: =IF($C$25=0,0,C4/$C$25) -> 0.03378159
A5: 2352-FID MID CAP IDX | B5: =COUNTIF('By Participant'!$C$5:$C$57,A5) -> 2 | C5: =SUMIF('By Participant'!$C$5:$C$57,A5,'By Participant'!$D$5:$D$57) -> 86827.462 | D5: =IF($C$25=0,0,C5/$C$25) -> 0.012660316
A6: 3005-FA FREEDOM 2015 K6 | B6: =COUNTIF('By Participant'!$C$5:$C$57,A6) -> 3 | C6: =SUMIF('By Participant'!$C$5:$C$57,A6,'By Participant'!$D$5:$D$57) -> 160717.43 | D6: =IF($C$25=0,0,C6/$C$25) -> 0.023434214
A7: 3006-FA FREEDOM 2020 K6 | B7: =COUNTIF('By Participant'!$C$5:$C$57,A7) -> 2 | C7: =SUMIF('By Participant'!$C$5:$C$57,A7,'By Participant'!$D$5:$D$57) -> 371266.61 | D7: =IF($C$25=0,0,C7/$C$25) -> 0.054134398
A8: 3007-FA FREEDOM 2025 K6 | B8: =COUNTIF('By Participant'!$C$5:$C$57,A8) -> 6 | C8: =SUMIF('By Participant'!$C$5:$C$57,A8,'By Participant'!$D$5:$D$57) -> 473823.66 | D8: =IF($C$25=0,0,C8/$C$25) -> 0.069088247
A9: 3008-FA FREEDOM 2030 K6 | B9: =COUNTIF('By Participant'!$C$5:$C$57,A9) -> 8 | C9: =SUMIF('By Participant'!$C$5:$C$57,A9,'By Participant'!$D$5:$D$57) -> 2853463.9 | D9: =IF($C$25=0,0,C9/$C$25) -> 0.41606368
A10: 3009-FA FREEDOM 2035 K6 | B10: =COUNTIF('By Participant'!$C$5:$C$57,A10) -> 2 | C10: =SUMIF('By Participant'!$C$5:$C$57,A10,'By Participant'!$D$5:$D$57) -> 691272.31 | D10: =IF($C$25=0,0,C10/$C$25) -> 0.10079444
A11: 3010-FA FREEDOM 2040 K6 | B11: =COUNTIF('By Participant'!$C$5:$C$57,A11) -> 8 | C11: =SUMIF('By Participant'!$C$5:$C$57,A11,'By Participant'!$D$5:$D$57) -> 688017.04 | D11: =IF($C$25=0,0,C11/$C$25) -> 0.10031979
A12: 3011-FA FREEDOM 2045 K6 | B12: =COUNTIF('By Participant'!$C$5:$C$57,A12) -> 1 | C12: =SUMIF('By Participant'!$C$5:$C$57,A12,'By Participant'!$D$5:$D$57) -> 83826.209 | D12: =IF($C$25=0,0,C12/$C$25) -> 0.012222703
A13: 3012-FA FREEDOM 2050 K6 | B13: =COUNTIF('By Participant'!$C$5:$C$57,A13) -> 1 | C13: =SUMIF('By Participant'!$C$5:$C$57,A13,'By Participant'!$D$5:$D$57) -> 1323.5557 | D13: =IF($C$25=0,0,C13/$C$25) -> 0.00019298771
A14: 3013-FA FREEDOM 2055 K6 | B14: =COUNTIF('By Participant'!$C$5:$C$57,A14) -> 2 | C14: =SUMIF('By Participant'!$C$5:$C$57,A14,'By Participant'!$D$5:$D$57) -> 138540.45 | D14: =IF($C$25=0,0,C14/$C$25) -> 0.020200589
A15: 3014-FA FREEDOM 2060 K6 | B15: =COUNTIF('By Participant'!$C$5:$C$57,A15) -> 2 | C15: =SUMIF('By Participant'!$C$5:$C$57,A15,'By Participant'!$D$5:$D$57) -> 84792.669 | D15: =IF($C$25=0,0,C15/$C$25) -> 0.012363622
... A24: OYQA-JPM LG CAP GROWTH R6 | B24: =COUNTIF('By Participant'!$C$5:$C$57,A24) -> 1 | C24: =SUMIF('By Participant'!$C$5:$C$57,A24,'By Participant'!$D$5:$D$57) -> 10665.895 | D24: =IF($C$25=0,0,C24/$C$25) -> 0.0015551945
A25: TOTAL | B25: =SUM(B4:B24) -> 53 | C25: =SUM(C4:C24) -> 6858238.3 | D25: =SUM(D4:D24) -> 1

Sheet Original Report
C1: Market Value
A2: Full Name | B2: Status | C2: 2328-FID 500 INDEX | D2: 2352-FID MID CAP IDX | E2: 3005-FA FREEDOM 2015 K6 | F2: 3006-FA FREEDOM 2020 K6 | G2: 3007-FA FREEDOM 2025 K6 | H2: 3008-FA FREEDOM 2030 K6 | I2: 3009-FA FREEDOM 2035 K6 | J2: 3010-FA FREEDOM 2040 K6 | K2: 3011-FA FREEDOM 2045 K6 | L2: 3012-FA FREEDOM 2050 K6 | M2: 3013-FA FREEDOM 2055 K6 | N2: 3014-FA FREEDOM 2060 K6 | O2: 3015-FA FREEDOM RETIRE K6 | P2: 3286-FA STRAT INCOME Z | Q2: OEM4-JPMORGAN INCOME R6 | R2: OIWD-BLKRK EQUITY DIV K | S2: OQTF-HARBOR SCG INST | T2: OUBE-AF EUPAC FUND R6 | U2: OUFP-AF NEW WORLD R6 | V2: OV6J-AS TREA PL MMKT SVC | W2: OYQA-JPM LG CAP GROWTH R6 | X2: Totals
A3: ACCOUNT, FORFEITURE | B3: A-ACTIVE | V3: 1283.97 | X3: =SUM(C3:W3) -> 1283.97
A4: ACCOUNT, RCP | B4: A-ACTIVE | V4: 1.63 | X4: =SUM(C4:W4) -> 1.63
A5: BAKER, CHARLES | B5: T-TERMINATED | E5: 291.83668 | X5: =SUM(C5:W5) -> 291.83668
A6: BETZ, LISA | B6: A-ACTIVE | C6: 97614.091 | D6: 17256.065 | Q6: 13307.687 | S6: 15904.985 | T6: 17055.215 | U6: 16972.363 | X6: =SUM(C6:W6) -> 178110.41
A7: BOUFORD, LAURIE | B7: T-TERMINATED | H7: 532.0123 | X7: =SUM(C7:W7) -> 532.0123
A8: CALLAHAN, TAYLOR | B8: A-ACTIVE | N8: 49487.259 | X8: =SUM(C8:W8) -> 49487.259
A9: CARTON, ANDREW P | B9: A-ACTIVE | G9: 133490.9 | O9: 113825.86 | V9: 520662.2 | X9: =SUM(C9:W9) -> 767978.96
A10: CARTON, CHRISTOPHER M | B10: A-ACTIVE | H10: 1422238.4 | X10: =SUM(C10:W10) -> 1422238.4
A11: CARTON, KATHLEEN | B11: A-ACTIVE | H11: 371297.42 | X11: =SUM(C11:W11) -> 371297.42
A12: CARTON, RACHEL | B12: A-ACTIVE | N12: 35305.41 | X12: =SUM(C12:W12) -> 35305.41
A13: CASLER, SANDRA J | B13: R-RETIRED | E13: 68333.247 | X13: =SUM(C13:W13) -> 68333.247
A14: CAVAZZONI, TINA | B14: A-ACTIVE | J14: 10648.245 | X14: =SUM(C14:W14) -> 10648.245
A15: CONFORTI, JOHN N | B15: A-ACTIVE | H15: 798248.21 | X15: =SUM(C15:W15) -> 798248.21
A16: CONWAY, CHRISTOPHER W | B16: A-ACTIVE | V16: 61706.2 | X16: =SUM(C16:W16) -> 61706.2
A17: COSTA, JENNIFER A | B17: A-ACTIVE | C17: 134068.11 | X17: =SUM(C17:W17) -> 134068.11
A18: COSTELLO, HEATHER | B18: A-ACTIVE | J18: 20590.63 | X18: =SUM(C18:W18) -> 20590.63
A19: DEROGATIS, ROSAMARIE | B19: T-TERMINATED | E19: 92092.342 | X19: =SUM(C19:W19) -> 92092.342
A20: DICECILIA, LISA | B20: E-ELIGIBLE | G20: 1823.8927 | X20: =SUM(C20:W20) -> 1823.8927
A21: DIMAGGIO, GINA | B21: A-ACTIVE | H21: 158925.97 | X21: =SUM(C21:W21) -> 158925.97
A22: FURRULE, LISA | B22: A-ACTIVE | H22: 4225.5353 | X22: =SUM(C22:W22) -> 4225.5353
A23: GARCIA, PAULA | B23: T-TERMINATED | J23: 4269.8065 | W23: 10665.895 | X23: =SUM(C23:W23) -> 14935.701
A24: GASSARO, KOREN E | B24: A-ACTIVE | J24: 108163.4 | X24: =SUM(C24:W24) -> 108163.4
A25: GAWRON, JOSEPH W | B25: A-ACTIVE | D25: 69571.396 | J25: 398061.47 | R25: 127715.02 | X25: =SUM(C25:W25) -> 595347.89
A26: GRABAS, JOSEPH | B26: A-ACTIVE | G26: 30102.663 | K26: 83826.209 | X26: =SUM(C26:W26) -> 113928.87
A27: GRABAS, PATRICIA | B27: A-ACTIVE | G27: 55974.71 | X27: =SUM(C27:W27) -> 55974.71
A28: GUTMAN, NANCY A | B28: A-ACTIVE | F28: 234827.8 | X28: =SUM(C28:W28) -> 234827.8
A29: ILLES, KIMBERLY | B29: T-TERMINATED | J29: 2538.0398 | X29: =SUM(C29:W29) -> 2538.0398
A30: LAYTON, ROBERT G | B30: A-ACTIVE | H30: 15371.937 | S30: 61135.486 | X30: =SUM(C30:W30) -> 76507.423
A31: LOCASCIO, NICOLE | B31: A-ACTIVE | J31: 15041.566 | X31: =SUM(C31:W31) -> 15041.566
A32: OSTOLAZA, PILAR | B32: A-ACTIVE | L32: 1323.5557 | X32: =SUM(C32:W32) -> 1323.5557
A33: PIKE, BRIELLE | B33: A-ACTIVE | M33: 34485.017 | X33: =SUM(C33:W33) -> 34485.017
A34: QUARANTELLO, ALYSE | B34: A-ACTIVE | I34: 72395.224 | X34: =SUM(C34:W34) -> 72395.224
A35: RIBECCA, CHRISTOPHER J | B35: A-ACTIVE | M35: 104055.44 | X35: =SUM(C35:W35) -> 104055.44
A36: SCENNA, DERRICK A | B36: A-ACTIVE | I36: 618877.08 | X36: =SUM(C36:W36) -> 618877.08
A37: TORRES, BETH | B37: A-ACTIVE | J37: 128703.88 | X37: =SUM(C37:W37) -> 128703.88
A38: VACCARO, DEBRA | B38: A-ACTIVE | H38: 82624.376 | X38: =SUM(C38:W38) -> 82624.376
A39: WARD, CYNTHIA M | B39: A-ACTIVE | G39: 242714.1 | X39: =SUM(C39:W39) -> 242714.1
A40: ZAPPOLA, SALLY A | B40: A-ACTIVE | F40: 136438.8 | G40: 9717.4026 | P40: 12847.584 | R40: 19600.763 | X40: =SUM(C40:W40) -> 178604.55
...
