Workbook

Sheet Cover
B2: TAX ESTIMATOR & PORTFOLIO TAX CALCULATOR
B3: For Financial Advisors and Their Clients
B5: This workbook provides two integrated calculators: 1) COMPLETE TAX ESTIMATOR - a full household federal, state, and local tax projection based on income, pre-tax contributions, investment income, deductions, and credits. 2) PORTFOLIO TAX ESTIMATOR - the incremental tax generated specifically by an investment portfolio (interest, dividends, capital gains), layered on top of salary income.
B11: IMPORTANT DISCLAIMER Tax estimates are for educational and financial-planning purposes only. Actual tax liability may differ based on individual circumstances, deductions, credits, tax elections, state/local rules, and other factors. This calculator does not provide tax, legal, or accounting advice. Consult a qualified tax professional regarding your individual situation.
B18: WORKBOOK CONTENTS
B19: Instructions | C19: How to use this workbook, color legend, navigation.
B20: Params_Federal | C20: Federal tax-parameter database by tax year (brackets, deductions, credits, limits).
B21: Params_State | C21: State-by-state tax parameter database (brackets, treatment of retirement/SS income).
B22: Params_Local | C22: Local / municipal tax parameter database.
B23: Calc1_Inputs | C23: Complete Tax Estimator - all household inputs.
B24: Calc1_Engine | C24: Complete Tax Estimator - calculation engine (shows all work).
B25: Calc1_Results | C25: Complete Tax Estimator - summary dashboard and charts.
B26: Calc2_Portfolio_Inputs | C26: Portfolio Tax Estimator - inputs.
B27: Calc2_Portfolio_Engine | C27: Portfolio Tax Estimator - incremental tax calculation engine.
B28: Calc2_Portfolio_Results | C28: Portfolio Tax Estimator - summary dashboard and charts.
B29: WhatIf_Scenarios | C29: Side-by-side scenario comparison tool (before / after).
B30: Tax_Loss_Harvesting | C30: Tax-loss harvesting savings estimator.
... B32: Assumptions_Disclaimer | C32: Full disclaimer and methodology / assumptions.
B37: Tax Year Coverage: 2024 and 2025 | Prepared for planning discussions - not a tax return.

Sheet Instructions
B2: HOW TO USE THIS WORKBOOK
B4: Color Legend
B5: Yellow / gold fill, blue text | C5: Input cell - change these to update the model.
B6: Black text | C6: Formula - calculated automatically. Do not overwrite.
B7: Green fill | C7: Link pulled from another tab (e.g., Parameters or another Calculator).
B8: Light blue fill, bold navy text | C8: Key result / summary output.
B10: Steps
B11: 1. Complete Tax Estimator: go to Calc1_Inputs, select filing status / tax year / state / locality, then fill in income, pre-tax contributions, investment income, deductions, and credits. Results flow automatically to Calc1_Engine and Calc1_Results.
B12: 2. Portfolio Tax Estimator: go to Calc2_Portfolio_Inputs, enter filing status, state, salary for each spouse, and portfolio income detail. Results flow to Calc2_Portfolio_Engine and Calc2_Portfolio_Results.
B13: 3. What-If Scenarios: use WhatIf_Scenarios to compare a baseline case against an alternative (e.g., loss harvesting, additional retirement contributions, extra dividend income).
B14: 4. Tax-Loss Harvesting: use Tax_Loss_Harvesting to estimate the tax savings of harvesting unrealized losses.
B15: 5. Retirement Contribution: use Retirement_Contribution to estimate the tax savings and after-tax cost of an additional pre-tax contribution.
B16: 6. All tax-law figures (brackets, deduction amounts, thresholds, limits) live on the Params_* tabs and can be updated for future tax years without changing any calculation logic.
B18: Disclaimer
B19: Tax estimates are for educational and financial-planning purposes only. Actual tax liability may differ based on individual circumstances, deductions, credits, tax elections, state/local rules, and other factors. This calculator does not provide tax, legal, or accounting advice. Consult a qualified tax professional regarding your individual situation.

Sheet Params_Federal
A1: FEDERAL TAX PARAMETER DATABASE
A2: All figures below are editable inputs. Update this tab to add a new tax year or refresh published IRS figures - no calculation logic elsewhere needs to change.
A4: A. Federal Ordinary Income Tax Brackets (7 brackets)
A5: Year | B5: Filing Status | C5: Key | D5: Rate 1 | E5: Min 1 | F5: Max 1 | G5: Rate 2 | H5: Min 2 | I5: Max 2 | J5: Rate 3 | K5: Min 3 | L5: Max 3 | M5: Rate 4 | N5: Min 4 | O5: Max 4 | P5: Rate 5 | Q5: Min 5 | R5: Max 5 | S5: Rate 6 | T5: Min 6 | U5: Max 6 | V5: Rate 7 | W5: Min 7 | X5: Max 7
A6: 2024 | B6: Single | C6: =A6&"|"&B6 | D6: 0.1 | E6: 0 | F6: =H6 | G6: 0.12 | H6: 11600 | I6: =K6 | J6: 0.22 | K6: 47150 | L6: =N6 | M6: 0.24 | N6: 100525 | O6: =Q6 | P6: 0.32 | Q6: 191950 | R6: =T6 | S6: 0.35 | T6: 243725 | U6: =W6 | V6: 0.37 | W6: 609350 | X6: 999999999
A7: 2024 | B7: Married Filing Jointly | C7: =A7&"|"&B7 | D7: 0.1 | E7: 0 | F7: =H7 | G7: 0.12 | H7: 23200 | I7: =K7 | J7: 0.22 | K7: 94300 | L7: =N7 | M7: 0.24 | N7: 201050 | O7: =Q7 | P7: 0.32 | Q7: 383900 | R7: =T7 | S7: 0.35 | T7: 487450 | U7: =W7 | V7: 0.37 | W7: 731200 | X7: 999999999
A8: 2024 | B8: Married Filing Separately | C8: =A8&"|"&B8 | D8: 0.1 | E8: 0 | F8: =H8 | G8: 0.12 | H8: 11600 | I8: =K8 | J8: 0.22 | K8: 47150 | L8: =N8 | M8: 0.24 | N8: 100525 | O8: =Q8 | P8: 0.32 | Q8: 191950 | R8: =T8 | S8: 0.35 | T8: 243725 | U8: =W8 | V8: 0.37 | W8: 365600 | X8: 999999999
A9: 2024 | B9: Head of Household | C9: =A9&"|"&B9 | D9: 0.1 | E9: 0 | F9: =H9 | G9: 0.12 | H9: 16550 | I9: =K9 | J9: 0.22 | K9: 63100 | L9: =N9 | M9: 0.24 | N9: 100500 | O9: =Q9 | P9: 0.32 | Q9: 191950 | R9: =T9 | S9: 0.35 | T9: 243700 | U9: =W9 | V9: 0.37 | W9: 609350 | X9: 999999999
A10: 2024 | B10: Qualifying Surviving Spouse | C10: =A10&"|"&B10 | D10: 0.1 | E10: 0 | F10: =H10 | G10: 0.12 | H10: 23200 | I10: =K10 | J10: 0.22 | K10: 94300 | L10: =N10 | M10: 0.24 | N10: 201050 | O10: =Q10 | P10: 0.32 | Q10: 383900 | R10: =T10 | S10: 0.35 | T10: 487450 | U10: =W10 | V10: 0.37 | W10: 731200 | X10: 999999999
A11: 2025 | B11: Single | C11: =A11&"|"&B11 | D11: 0.1 | E11: 0 | F11: =H11 | G11: 0.12 | H11: 11925 | I11: =K11 | J11: 0.22 | K11: 48475 | L11: =N11 | M11: 0.24 | N11: 103350 | O11: =Q11 | P11: 0.32 | Q11: 197300 | R11: =T11 | S11: 0.35 | T11: 250525 | U11: =W11 | V11: 0.37 | W11: 626350 | X11: 999999999
A12: 2025 | B12: Married Filing Jointly | C12: =A12&"|"&B12 | D12: 0.1 | E12: 0 | F12: =H12 | G12: 0.12 | H12: 23850 | I12: =K12 | J12: 0.22 | K12: 96950 | L12: =N12 | M12: 0.24 | N12: 206700 | O12: =Q12 | P12: 0.32 | Q12: 394600 | R12: =T12 | S12: 0.35 | T12: 501050 | U12: =W12 | V12: 0.37 | W12: 751600 | X12: 999999999
A13: 2025 | B13: Married Filing Separately | C13: =A13&"|"&B13 | D13: 0.1 | E13: 0 | F13: =H13 | G13: 0.12 | H13: 11925 | I13: =K13 | J13: 0.22 | K13: 48475 | L13: =N13 | M13: 0.24 | N13: 103350 | O13: =Q13 | P13: 0.32 | Q13: 197300 | R13: =T13 | S13: 0.35 | T13: 250525 | U13: =W13 | V13: 0.37 | W13: 375800 | X13: 999999999
A14: 2025 | B14: Head of Household | C14: =A14&"|"&B14 | D14: 0.1 | E14: 0 | F14: =H14 | G14: 0.12 | H14: 17000 | I14: =K14 | J14: 0.22 | K14: 64850 | L14: =N14 | M14: 0.24 | N14: 103350 | O14: =Q14 | P14: 0.32 | Q14: 197300 | R14: =T14 | S14: 0.35 | T14: 250500 | U14: =W14 | V14: 0.37 | W14: 626350 | X14: 999999999
A15: 2025 | B15: Qualifying Surviving Spouse | C15: =A15&"|"&B15 | D15: 0.1 | E15: 0 | F15: =H15 | G15: 0.12 | H15: 23850 | I15: =K15 | J15: 0.22 | K15: 96950 | L15: =N15 | M15: 0.24 | N15: 206700 | O15: =Q15 | P15: 0.32 | Q15: 394600 | R15: =T15 | S15: 0.35 | T15: 501050 | U15: =W15 | V15: 0.37 | W15: 751600 | X15: 999999999
A17: B. Long-Term Capital Gains / Qualified Dividend Brackets (0% / 15% / 20%)
A18: Year | B18: Filing Status | C18: Key | D18: Rate 1 | E18: Min 1 | F18: Max 1 | G18: Rate 2 | H18: Min 2 | I18: Max 2 | J18: Rate 3 | K18: Min 3 | L18: Max 3
A19: 2024 | B19: Single | C19: =A19&"|"&B19 | D19: 0 | E19: 0 | F19: =H19 | G19: 0.15 | H19: 47025 | I19: =K19 | J19: 0.2 | K19: 518900 | L19: 999999999
A20: 2024 | B20: Married Filing Jointly | C20: =A20&"|"&B20 | D20: 0 | E20: 0 | F20: =H20 | G20: 0.15 | H20: 94050 | I20: =K20 | J20: 0.2 | K20: 583750 | L20: 999999999
A21: 2024 | B21: Married Filing Separately | C21: =A21&"|"&B21 | D21: 0 | E21: 0 | F21: =H21 | G21: 0.15 | H21: 47025 | I21: =K21 | J21: 0.2 | K21: 291850 | L21: 999999999
A22: 2024 | B22: Head of Household | C22: =A22&"|"&B22 | D22: 0 | E22: 0 | F22: =H22 | G22: 0.15 | H22: 63000 | I22: =K22 | J22: 0.2 | K22: 551350 | L22: 999999999
A23: 2024 | B23: Qualifying Surviving Spouse | C23: =A23&"|"&B23 | D23: 0 | E23: 0 | F23: =H23 | G23: 0.15 | H23: 94050 | I23: =K23 | J23: 0.2 | K23: 583750 | L23: 999999999
A24: 2025 | B24: Single | C24: =A24&"|"&B24 | D24: 0 | E24: 0 | F24: =H24 | G24: 0.15 | H24: 48350 | I24: =K24 | J24: 0.2 | K24: 533400 | L24: 999999999
A25: 2025 | B25: Married Filing Jointly | C25: =A25&"|"&B25 | D25: 0 | E25: 0 | F25: =H25 | G25: 0.15 | H25: 96700 | I25: =K25 | J25: 0.2 | K25: 600050 | L25: 999999999
A26: 2025 | B26: Married Filing Separately | C26: =A26&"|"&B26 | D26: 0 | E26: 0 | F26: =H26 | G26: 0.15 | H26: 48350 | I26: =K26 | J26: 0.2 | K26: 300000 | L26: 999999999
A27: 2025 | B27: Head of Household | C27: =A27&"|"&B27 | D27: 0 | E27: 0 | F27: =H27 | G27: 0.15 | H27: 64750 | I27: =K27 | J27: 0.2 | K27: 566700 | L27: 999999999
A28: 2025 | B28: Qualifying Surviving Spouse | C28: =A28&"|"&B28 | D28: 0 | E28: 0 | F28: =H28 | G28: 0.15 | H28: 96700 | I28: =K28 | J28: 0.2 | K28: 600050 | L28: 999999999
A30: C. Standard Deduction
A31: Year | B31: Filing Status | C31: Key | D31: Standard Deduction | E31: Addl. Deduction (65+/Blind, per occurrence)
A32: 2024 | B32: Single | C32: =A32&"|"&B32 | D32: 14600 | E32: 1950
A33: 2024 | B33: Married Filing Jointly | C33: =A33&"|"&B33 | D33: 29200 | E33: 1550
A34: 2024 | B34: Married Filing Separately | C34: =A34&"|"&B34 | D34: 14600 | E34: 1550
A35: 2024 | B35: Head of Household | C35: =A35&"|"&B35 | D35: 21900 | E35: 1950
A36: 2024 | B36: Qualifying Surviving Spouse | C36: =A36&"|"&B36 | D36: 29200 | E36: 1550
A37: 2025 | B37: Single | C37: =A37&"|"&B37 | D37: 15000 | E37: 2000
A38: 2025 | B38: Married Filing Jointly | C38: =A38&"|"&B38 | D38: 30000 | E38: 1600
A39: 2025 | B39: Married Filing Separately | C39: =A39&"|"&B39 | D39: 15000 | E39: 1600
A40: 2025 | B40: Head of Household | C40: =A40&"|"&B40 | D40: 22500 | E40: 2000
A41: 2025 | B41: Qualifying Surviving Spouse | C41: =A41&"|"&B41 | D41: 30000 | E41: 1600
A43: D. NIIT, Additional Medicare Tax & Capital-Loss Thresholds (fixed by statute, not inflation-indexed)
A44: Filing Status | B44: NIIT MAGI Threshold | C44: Addl. Medicare Threshold | D44: Capital Loss Limit vs. Ordinary Income
...

Sheet Params_State
A1: STATE TAX PARAMETER DATABASE
A2: Covers 31 states + DC representing no-tax, flat-tax, and progressive-tax structures, plus a Manual Entry option for any state not listed. Brackets/treatment are approximate (~2024-2025 law) for planning purposes - verify against current state guidance before client use.
A4: A. State Master List & Income Treatment
A5: State Code | B5: State Name | C5: Tax Type | D5: Social Security Taxable? | E5: Retirement Income (Pension/401k/IRA) Exempt? | F5: Std. Deduction (Single) | G5: Std. Deduction (MFJ) | H5: Notes / Simplifications
A6: FL | B6: Florida | C6: None | D6: No | E6: Yes | F6: 0 | G6: 0 | H6: No state income tax.
A7: TX | B7: Texas | C7: None | D7: No | E7: Yes | F7: 0 | G7: 0 | H7: No state income tax.
A8: WA | B8: Washington | C8: None | D8: No | E8: Yes | F8: 0 | G8: 0 | H8: No state income tax (capital gains excise tax on high earners not modeled).
A9: NV | B9: Nevada | C9: None | D9: No | E9: Yes | F9: 0 | G9: 0 | H9: No state income tax.
A10: WY | B10: Wyoming | C10: None | D10: No | E10: Yes | F10: 0 | G10: 0 | H10: No state income tax.
A11: SD | B11: South Dakota | C11: None | D11: No | E11: Yes | F11: 0 | G11: 0 | H11: No state income tax.
A12: AK | B12: Alaska | C12: None | D12: No | E12: Yes | F12: 0 | G12: 0 | H12: No state income tax.
A13: TN | B13: Tennessee | C13: None | D13: No | E13: Yes | F13: 0 | G13: 0 | H13: No state income tax.
A14: CO | B14: Colorado | C14: Flat | D14: No | E14: No | F14: 0 | G14: 0 | H14: Flat rate; SS generally subtracted.
A15: IL | B15: Illinois | C15: Flat | D15: No | E15: Yes | F15: 0 | G15: 0 | H15: Flat rate; retirement income generally exempt; SS exempt.
A16: IN | B16: Indiana | C16: Flat | D16: No | E16: No | F16: 0 | G16: 0 | H16: Flat rate.
A17: MI | B17: Michigan | C17: Flat | D17: No | E17: Yes | F17: 0 | G17: 0 | H17: Flat rate; retirement income partially/fully exempt depending on birth year (simplified: exempt).
... A37: OTHER | B37: Other (Manual Entry) | C37: Manual | D37: N/A | E37: N/A | F37: 0 | G37: 0 | H37: Uses the manual effective state tax rate entered on the Inputs tab.
A39: B. State Income Tax Brackets (unified 8-bracket format; category Single covers Single/MFS/HOH, MFJ covers MFJ/QSS)
A40: State Code | B40: Filing Category | C40: Key | D40: Rate 1 | E40: Min 1 | F40: Max 1 | G40: Rate 2 | H40: Min 2 | I40: Max 2 | J40: Rate 3 | K40: Min 3 | L40: Max 3 | M40: Rate 4 | N40: Min 4 | O40: Max 4 | P40: Rate 5 | Q40: Min 5 | R40: Max 5 | S40: Rate 6 | T40: Min 6 | U40: Max 6 | V40: Rate 7 | W40: Min 7 | X40: Max 7 | Y40: Rate 8 | Z40: Min 8 | AA40: Max 8
A41: FL | B41: Single | C41: =A41&"|"&B41 | D41: 0 | E41: 0 | F41: =H41 | G41: 0 | H41: 999999999 | I41: =K41 | J41: 0 | K41: 999999999 | L41: =N41 | M41: 0 | N41: 999999999 | O41: =Q41 | P41: 0 | Q41: 999999999 | R41: =T41 | S41: 0 | T41: 999999999 | U41: =W41 | V41: 0 | W41: 999999999 | X41: =Z41 | Y41: 0 | Z41: 999999999 | AA41: 999999999
A42: FL | B42: MFJ | C42: =A42&"|"&B42 | D42: 0 | E42: 0 | F42: =H42 | G42: 0 | H42: 999999999 | I42: =K42 | J42: 0 | K42: 999999999 | L42: =N42 | M42: 0 | N42: 999999999 | O42: =Q42 | P42: 0 | Q42: 999999999 | R42: =T42 | S42: 0 | T42: 999999999 | U42: =W42 | V42: 0 | W42: 999999999 | X42: =Z42 | Y42: 0 | Z42: 999999999 | AA42: 999999999
A43: TX | B43: Single | C43: =A43&"|"&B43 | D43: 0 | E43: 0 | F43: =H43 | G43: 0 | H43: 999999999 | I43: =K43 | J43: 0 | K43: 999999999 | L43: =N43 | M43: 0 | N43: 999999999 | O43: =Q43 | P43: 0 | Q43: 999999999 | R43: =T43 | S43: 0 | T43: 999999999 | U43: =W43 | V43: 0 | W43: 999999999 | X43: =Z43 | Y43: 0 | Z43: 999999999 | AA43: 999999999
A44: TX | B44: MFJ | C44: =A44&"|"&B44 | D44: 0 | E44: 0 | F44: =H44 | G44: 0 | H44: 999999999 | I44: =K44 | J44: 0 | K44: 999999999 | L44: =N44 | M44: 0 | N44: 999999999 | O44: =Q44 | P44: 0 | Q44: 999999999 | R44: =T44 | S44: 0 | T44: 999999999 | U44: =W44 | V44: 0 | W44: 999999999 | X44: =Z44 | Y44: 0 | Z44: 999999999 | AA44: 999999999
A45: WA | B45: Single | C45: =A45&"|"&B45 | D45: 0 | E45: 0 | F45: =H45 | G45: 0 | H45: 999999999 | I45: =K45 | J45: 0 | K45: 999999999 | L45: =N45 | M45: 0 | N45: 999999999 | O45: =Q45 | P45: 0 | Q45: 999999999 | R45: =T45 | S45: 0 | T45: 999999999 | U45: =W45 | V45: 0 | W45: 999999999 | X45: =Z45 | Y45: 0 | Z45: 999999999 | AA45: 999999999
A46: WA | B46: MFJ | C46: =A46&"|"&B46 | D46: 0 | E46: 0 | F46: =H46 | G46: 0 | H46: 999999999 | I46: =K46 | J46: 0 | K46: 999999999 | L46: =N46 | M46: 0 | N46: 999999999 | O46: =Q46 | P46: 0 | Q46: 999999999 | R46: =T46 | S46: 0 | T46: 999999999 | U46: =W46 | V46: 0 | W46: 999999999 | X46: =Z46 | Y46: 0 | Z46: 999999999 | AA46: 999999999
A47: NV | B47: Single | C47: =A47&"|"&B47 | D47: 0 | E47: 0 | F47: =H47 | G47: 0 | H47: 999999999 | I47: =K47 | J47: 0 | K47: 999999999 | L47: =N47 | M47: 0 | N47: 999999999 | O47: =Q47 | P47: 0 | Q47: 999999999 | R47: =T47 | S47: 0 | T47: 999999999 | U47: =W47 | V47: 0 | W47: 999999999 | X47: =Z47 | Y47: 0 | Z47: 999999999 | AA47: 999999999
A48: NV | B48: MFJ | C48: =A48&"|"&B48 | D48: 0 | E48: 0 | F48: =H48 | G48: 0 | H48: 999999999 | I48: =K48 | J48: 0 | K48: 999999999 | L48: =N48 | M48: 0 | N48: 999999999 | O48: =Q48 | P48: 0 | Q48: 999999999 | R48: =T48 | S48: 0 | T48: 999999999 | U48: =W48 | V48: 0 | W48: 999999999 | X48: =Z48 | Y48: 0 | Z48: 999999999 | AA48: 999999999
A49: WY | B49: Single | C49: =A49&"|"&B49 | D49: 0 | E49: 0 | F49: =H49 | G49: 0 | H49: 999999999 | I49: =K49 | J49: 0 | K49: 999999999 | L49: =N49 | M49: 0 | N49: 999999999 | O49: =Q49 | P49: 0 | Q49: 999999999 | R49: =T49 | S49: 0 | T49: 999999999 | U49: =W49 | V49: 0 | W49: 999999999 | X49: =Z49 | Y49: 0 | Z49: 999999999 | AA49: 999999999
A50: WY | B50: MFJ | C50: =A50&"|"&B50 | D50: 0 | E50: 0 | F50: =H50 | G50: 0 | H50: 999999999 | I50: =K50 | J50: 0 | K50: 999999999 | L50: =N50 | M50: 0 | N50: 999999999 | O50: =Q50 | P50: 0 | Q50: 999999999 | R50: =T50 | S50: 0 | T50: 999999999 | U50: =W50 | V50: 0 | W50: 999999999 | X50: =Z50 | Y50: 0 | Z50: 999999999 | AA50: 999999999
A51: SD | B51: Single | C51: =A51&"|"&B51 | D51: 0 | E51: 0 | F51: =H51 | G51: 0 | H51: 999999999 | I51: =K51 | J51: 0 | K51: 999999999 | L51: =N51 | M51: 0 | N51: 999999999 | O51: =Q51 | P51: 0 | Q51: 999999999 | R51: =T51 | S51: 0 | T51: 999999999 | U51: =W51 | V51: 0 | W51: 999999999 | X51: =Z51 | Y51: 0 | Z51: 999999999 | AA51: 999999999
A52: SD | B52: MFJ | C52: =A52&"|"&B52 | D52: 0 | E52: 0 | F52: =H52 | G52: 0 | H52: 999999999 | I52: =K52 | J52: 0 | K52: 999999999 | L52: =N52 | M52: 0 | N52: 999999999 | O52: =Q52 | P52: 0 | Q52: 999999999 | R52: =T52 | S52: 0 | T52: 999999999 | U52: =W52 | V52: 0 | W52: 999999999 | X52: =Z52 | Y52: 0 | Z52: 999999999 | AA52: 999999999
... A104: OTHER | B104: MFJ | C104: =A104&"|"&B104 | D104: 0 | E104: 0 | F104: =H104 | G104: 0 | H104: 999999999 | I104: =K104 | J104: 0 | K104: 999999999 | L104: =N104 | M104: 0 | N104: 999999999 | O104: =Q104 | P104: 0 | Q104: 999999999 | R104: =T104 | S104: 0 | T104: 999999999 | U104: =W104 | V104: 0 | W104: 999999999 | X104: =Z104 | Y104: 0 | Z104: 999999999 | AA104: 999999999

Sheet Params_Local
A1: LOCAL / MUNICIPAL TAX PARAMETER DATABASE
A2: A representative sample of localities with earned-income or wage taxes. "Earned" bases apply the rate to wages/self-employment income only (typical of municipal EIT regimes); "All" applies to total state taxable income; "PctState" applies as a percentage of the computed state tax (county piggyback style). Select "Other (Manual Entry)" to enter a custom local rate.
A4: Local Tax Table
A5: Locality Code | B5: Locality Name | C5: State | D5: Tax Base | E5: Rate | F5: Notes
A6: NYC | B6: New York City | C6: NY | D6: All | E6: 0.03648 | F6: Approximate blended NYC resident rate.
A7: YONK | B7: Yonkers (NY) | C7: NY | D7: PctState | E7: 0.1675 | F7: Resident surcharge as % of NY State tax.
A8: PHIL | B8: Philadelphia, PA | C8: PA | D8: Earned | E8: 0.0375 | F8: Philadelphia wage tax (resident).
A9: PIT | B9: Pittsburgh, PA | C9: PA | D9: Earned | E9: 0.03 | F9: Local earned income tax (approx.).
A10: DET | B10: Detroit, MI | C10: MI | D10: Earned | E10: 0.024 | F10: Detroit resident income tax.
A11: COL | B11: Columbus, OH | C11: OH | D11: Earned | E11: 0.025 | F11: Ohio municipal income tax (approx.).
A12: CIN | B12: Cincinnati, OH | C12: OH | D12: Earned | E12: 0.019 | F12: Ohio municipal income tax (approx.).
A13: CLE | B13: Cleveland, OH | C13: OH | D13: Earned | E13: 0.025 | F13: Ohio municipal income tax (approx.).
A14: MDCO | B14: Maryland County (avg.) | C14: MD | D14: PctState | E14: 0.32 | F14: Average MD county piggyback tax as % of state taxable income equivalent (approx.).
A15: INCO | B15: Indiana County (avg.) | C15: IN | D15: Earned | E15: 0.0165 | F15: Average Indiana county income tax (approx.).
A16: KCMO | B16: Kansas City, MO | C16: MO | D16: Earned | E16: 0.01 | F16: Local earnings tax.
A17: STL | B17: St. Louis, MO | C17: MO | D17: Earned | E17: 0.01 | F17: Local earnings tax.
A18: NONE | B18: None / Not Applicable | D18: None | E18: 0 | F18: No local tax.
A19: OTHER | B19: Other (Manual Entry) | D19: Manual | E19: 0 | F19: Enter a custom local rate on the Inputs tab.

Sheet Calc1_Inputs
A1: CALCULATOR 1: COMPLETE TAX ESTIMATOR - INPUTS
A2: Enter all values in the gold input cells. Filing status, tax year, state, and locality drive every downstream calculation.
A4: Household Setup
B5: Filing Status | C5: Married Filing Jointly
B6: Tax Year | C6: 2025
B7: State of Residence | C7: California
B8: State Tax Rate if 'Other (Manual Entry)' Selected | C8: 0.05
B9: Locality / City | C9: None / Not Applicable
B10: Local Tax Rate if 'Other (Manual Entry)' Selected | C10: 0
B11: Number of Qualifying Children (under 17, for Child Tax Credit) | C11: 2
B12: Number of Other Dependents | C12: 0
B13: Number of Taxpayers Age 65+ or Blind (additional std. deduction) | C13: 0
A15: Earned & Other Income
B16: Income Item | C16: Individual 1 | D16: Individual 2 / Spouse | E16: Household Total
B17: W-2 Wages / Salary | C17: 165000 | D17: 98000 | E17: =C17+D17
B18: Bonus | C18: 20000 | D18: 0 | E18: =C18+D18
B19: Commissions | C19: 0 | D19: 0 | E19: =C19+D19
B20: Self-Employment Income (net) | C20: 0 | D20: 0 | E20: =C20+D20
B21: Partnership / S-Corp Income (K-1, non-investment) | C21: 0 | D21: 0 | E21: =C21+D21
B22: Other Ordinary Income | C22: 0 | D22: 0 | E22: =C22+D22
B23: Rental Income | C23: 0 | D23: 0 | E23: =C23+D23
B24: Pension Income | C24: 0 | D24: 0 | E24: =C24+D24
B25: Social Security Income | C25: 0 | D25: 0 | E25: =C25+D25
B26: IRA Distributions | C26: 0 | D26: 0 | E26: =C26+D26
B27: 401(k) Distributions | C27: 0 | D27: 0 | E27: =C27+D27
B28: Annuity Income | C28: 0 | D28: 0 | E28: =C28+D28
B29: Other Taxable Income | C29: 0 | D29: 0 | E29: =C29+D29
B30: Total Household Income | E30: =SUM(E17:E29)
A32: Pre-Tax Contributions (defaults reflect typical treatment - review each Y/N)
B33: Contribution | C33: Individual 1 | D33: Individual 2 / Spouse | E33: Household Total | F33: Reduces Federal Taxable? | G33: Reduces State Taxable? | H33: Reduces FICA Wages?
B34: Traditional 401(k) | C34: 15000 | D34: 9000 | E34: =C34+D34 | F34: Y | G34: Y | H34: N
B35: Traditional 403(b) | C35: 0 | D35: 0 | E35: =C35+D35 | F35: Y | G35: Y | H35: N
B36: Traditional 457(b) | C36: 0 | D36: 0 | E36: =C36+D36 | F36: Y | G36: Y | H36: N
B37: SIMPLE IRA | C37: 0 | D37: 0 | E37: =C37+D37 | F37: Y | G37: Y | H37: Y
B38: SEP IRA | C38: 0 | D38: 0 | E38: =C38+D38 | F38: Y | G38: Y | H38: N
B39: Traditional IRA (deductible) | C39: 0 | D39: 0 | E39: =C39+D39 | F39: Y | G39: Y | H39: N
B40: HSA Contributions | C40: 4300 | D40: 0 | E40: =C40+D40 | F40: Y | G40: Y | H40: Y
B41: FSA Contributions | C41: 0 | D41: 0 | E41: =C41+D41 | F41: Y | G41: Y | H41: Y
B42: Other Eligible Pre-Tax Contributions | C42: 0 | D42: 0 | E42: =C42+D42 | F42: Y | G42: Y | H42: N
A44: Investment Income (household total)
...

Sheet Calc1_Engine
A1: CALCULATOR 1 ENGINE - SHOWS ALL UNDERLYING CALCULATIONS
A2: Every figure below is a live formula referencing Calc1_Inputs and the Params_* parameter tables. Nothing is hardcoded.
K3: WORKING LOOKUP TABLES (helper cells - not for direct editing)
A4: 1. Capital Gain / Loss Netting | K4: Filing Status | L4: ='Calc1_Inputs'!C5
B5: Net Short-Term Gain / (Loss) | C5: =(Calc1_Inputs!C50-Calc1_Inputs!C51) | K5: Tax Year | L5: ='Calc1_Inputs'!C6
B6: Net Long-Term Gain / (Loss), net of carryforward | C6: =(Calc1_Inputs!C52-Calc1_Inputs!C53-Calc1_Inputs!C54) | K6: Federal Key | L6: =L5&"|"&L4
B7: Combined Net Capital Gain / (Loss) | C7: =(C5+C6) | K7: Fed Bracket Row# | L7: =MATCH(L6,Params_Federal!$C$6:$C$15,0)
B8: Capital Loss Limit vs. Ordinary Income | C8: =INDEX(Params_Federal!$D$45:$D$49,L12) | K8: LTCG Bracket Row# | L8: =MATCH(L6,Params_Federal!$C$19:$C$28,0)
B9: Ordinary-Taxed Capital Gain / (Loss Deduction, capped) | C9: =IF(C7<=0,MAX(C7,-C8),IF(AND(C5>=0,C6>=0),C5,IF(AND(C5<0,C6>=0),0,IF(AND(C5>=0,C6<0),C7,0)))) | K9: StdDed Row# | L9: =MATCH(L6,Params_Federal!$C$32:$C$41,0)
B10: Preferential (LTCG-Rate) Net Capital Gain | C10: =IF(C7<=0,0,IF(AND(C5>=0,C6>=0),C6,IF(AND(C5<0,C6>=0),C7,IF(AND(C5>=0,C6<0),0,0)))) | K10: SALT Row# | L10: =MATCH(L6,Params_Federal!$C$53:$C$62,0)
B11: Capital-Loss Carryforward to Future Years | C11: =IF(C7<=0,C7-MAX(C7,-C8),0) | D11: Negative = amount available to carry forward | K11: Savers Row# | L11: =MATCH(L6,Params_Federal!$C$85:$C$94,0)
K12: Status Row# (NIIT/AddlMed/CapLoss) | L12: =MATCH(L4,Params_Federal!$A$45:$A$49,0)
A13: 2. Pre-Tax Contributions - Federal / State / FICA Treatment | K13: Year Row# (CTC) | L13: =MATCH(L5,Params_Federal!$A$76:$A$77,0)
B14: Contributions Reducing Federal Taxable Income | C14: =SUMPRODUCT((Calc1_Inputs!$F$34:$F$42="Y")*Calc1_Inputs!$E$34:$E$42) | K14: Year Row# (Payroll) | L14: =MATCH(L5,Params_Federal!$A$66:$A$67,0)
B15: Contributions Reducing State Taxable Income | C15: =SUMPRODUCT((Calc1_Inputs!$G$34:$G$42="Y")*Calc1_Inputs!$E$34:$E$42) | K15: State Name | L15: ='Calc1_Inputs'!C7
B16: Contributions Reducing FICA Wages - Individual 1 | C16: =SUMPRODUCT((Calc1_Inputs!$H$34:$H$42="Y")*Calc1_Inputs!$C$34:$C$42) | K16: State Code | L16: =INDEX(Params_State!$A$6:$A$37,MATCH(L15,Params_State!$B$6:$B$37,0))
B17: Contributions Reducing FICA Wages - Individual 2 | C17: =SUMPRODUCT((Calc1_Inputs!$H$34:$H$42="Y")*Calc1_Inputs!$D$34:$D$42) | K17: State Category | L17: =IF(OR(L4="Married Filing Jointly",L4="Qualifying Surviving Spouse"),"MFJ","Single")
B18: FICA Wages - Individual 1 (W-2 + Bonus + Commissions, less FICA-exempt contrib.) | C18: =(Calc1_Inputs!C17+Calc1_Inputs!C18+Calc1_Inputs!C19)-C16 | K18: State Key | L18: =L16&"|"&L17
B19: FICA Wages - Individual 2 (W-2 + Bonus + Commissions, less FICA-exempt contrib.) | C19: =(Calc1_Inputs!D17+Calc1_Inputs!D18+Calc1_Inputs!D19)-C17 | K19: State Bracket Row# | L19: =MATCH(L18,Params_State!$C$41:$C$104,0)
K20: State Master Row# | L20: =MATCH(L16,Params_State!$A$6:$A$37,0)
A21: 3. Self-Employment Tax | K21: Locality Name | L21: ='Calc1_Inputs'!C9
B22: SS Wage Base (selected tax year) | C22: =INDEX(Params_Federal!$B$66:$B$67,L14) | K22: Locality Row# | L22: =MATCH(L21,Params_Local!$B$6:$B$19,0)
B23: SS Rate - Self-Employed | C23: =INDEX(Params_Federal!$D$66:$D$67,L14)
B24: Medicare Rate - Self-Employed | C24: =INDEX(Params_Federal!$F$66:$F$67,L14) | K24: Federal Ordinary Brackets
B25: SE Net Earnings Factor | C25: =INDEX(Params_Federal!$G$66:$G$67,L14) | K25: =INDEX(Params_Federal!D$6:D$1005,L7) | L25: =INDEX(Params_Federal!E$6:E$1005,L7) | M25: =INDEX(Params_Federal!F$6:F$1005,L7)
B26: Net SE Earnings - Individual 1 | C26: =Calc1_Inputs!C20*C25 | K26: =INDEX(Params_Federal!G$6:G$1005,L7) | L26: =INDEX(Params_Federal!H$6:H$1005,L7) | M26: =INDEX(Params_Federal!I$6:I$1005,L7)
B27: Net SE Earnings - Individual 2 | C27: =Calc1_Inputs!D20*C25 | K27: =INDEX(Params_Federal!J$6:J$1005,L7) | L27: =INDEX(Params_Federal!K$6:K$1005,L7) | M27: =INDEX(Params_Federal!L$6:L$1005,L7)
B28: SS-Taxable SE Earnings - Individual 1 (after wages already subject to SS) | C28: =MAX(0,MIN(C26,C22-C18)) | K28: =INDEX(Params_Federal!M$6:M$1005,L7) | L28: =INDEX(Params_Federal!N$6:N$1005,L7) | M28: =INDEX(Params_Federal!O$6:O$1005,L7)
B29: SS-Taxable SE Earnings - Individual 2 (after wages already subject to SS) | C29: =MAX(0,MIN(C27,C22-C19)) | K29: =INDEX(Params_Federal!P$6:P$1005,L7) | L29: =INDEX(Params_Federal!Q$6:Q$1005,L7) | M29: =INDEX(Params_Federal!R$6:R$1005,L7)
B30: Self-Employment Tax - Individual 1 | C30: =(C28*C23)+(C26*C24) | K30: =INDEX(Params_Federal!S$6:S$1005,L7) | L30: =INDEX(Params_Federal!T$6:T$1005,L7) | M30: =INDEX(Params_Federal!U$6:U$1005,L7)
B31: Self-Employment Tax - Individual 2 | C31: =(C29*C23)+(C27*C24) | K31: =INDEX(Params_Federal!V$6:V$1005,L7) | L31: =INDEX(Params_Federal!W$6:W$1005,L7) | M31: =INDEX(Params_Federal!X$6:X$1005,L7)
B32: Total Self-Employment Tax | C32: =(C30+C31)
B33: Deductible Half of Self-Employment Tax (adjustment to income) | C33: =C32/2 | K33: LTCG / QDI Brackets
K34: =INDEX(Params_Federal!D$19:D$1018,L8) | L34: =INDEX(Params_Federal!E$19:E$1018,L8) | M34: =INDEX(Params_Federal!F$19:F$1018,L8)
A35: 4. Gross Income | K35: =INDEX(Params_Federal!G$19:G$1018,L8) | L35: =INDEX(Params_Federal!H$19:H$1018,L8) | M35: =INDEX(Params_Federal!I$19:I$1018,L8)
B36: Total Household Earned & Other Income | C36: =Calc1_Inputs!E30 | K36: =INDEX(Params_Federal!J$19:J$1018,L8) | L36: =INDEX(Params_Federal!K$19:K$1018,L8) | M36: =INDEX(Params_Federal!L$19:L$1018,L8)
B37: Qualified Dividends | C37: =Calc1_Inputs!C46
B38: Ordinary Dividends | C38: =Calc1_Inputs!C47 | K38: State Brackets
B39: Taxable Interest | C39: =Calc1_Inputs!C48 | K39: =INDEX(Params_State!D$41:D$1040,L19) | L39: =INDEX(Params_State!E$41:E$1040,L19) | M39: =INDEX(Params_State!F$41:F$1040,L19)
B40: REIT Distributions | C40: =Calc1_Inputs!C55 | K40: =INDEX(Params_State!G$41:G$1040,L19) | L40: =INDEX(Params_State!H$41:H$1040,L19) | M40: =INDEX(Params_State!I$41:I$1040,L19)
...

Sheet Calc1_Results
A1: CALCULATOR 1: COMPLETE TAX ESTIMATOR - RESULTS
A2: For planning purposes only - not tax advice. See Assumptions_Disclaimer tab.
B4: Estimated Total Tax | C4: Effective Tax Rate | D4: Marginal Federal Rate | E4: Estimated After-Tax Income | F4: Tax Attributable to Investments (approx.)
B5: =Calc1_Engine!C137 | C5: =Calc1_Engine!C138 | D5: =Calc1_Engine!C139 | E5: =Calc1_Engine!C143 | F5: =(Calc1_Engine!C75+Calc1_Engine!C82+Calc1_Engine!C139*(Calc1_Inputs!C47+Calc1_Inputs!C48))
B7: Tax Summary | H7: Tax Component | I7: Amount
B8: Gross Income | C8: =Calc1_Engine!C44 | H8: Federal Income Tax | I8: =Calc1_Engine!C74
B9: Adjustments to Income | C9: =-Calc1_Engine!C49 | H9: Capital Gains / QDI Tax | I9: =Calc1_Engine!C75
B10: Adjusted Gross Income (AGI) | C10: =Calc1_Engine!C50 | H10: NIIT | I10: =Calc1_Engine!C82
B11: Deduction (Standard or Itemized) | C11: =-Calc1_Engine!C65 | H11: Payroll Taxes | I11: =Calc1_Engine!C98
B12: Taxable Income | C12: =Calc1_Engine!C69 | H12: State Tax | I12: =Calc1_Engine!C127
B13: Federal Income Tax (ordinary) | C13: =Calc1_Engine!C74 | H13: Local Tax | I13: =Calc1_Engine!C134
B14: Capital Gains / QDI Tax | C14: =Calc1_Engine!C75
B15: Net Investment Income Tax (NIIT) | C15: =Calc1_Engine!C82 | H15: Income vs. Tax | I15: Amount
B16: Payroll Taxes (FICA + SE + Addl. Medicare) | C16: =Calc1_Engine!C98 | H16: Gross Income | I16: =Calc1_Engine!C44
B17: State Tax | C17: =Calc1_Engine!C127 | H17: Estimated Total Tax | I17: =Calc1_Engine!C137
B18: Local Tax | C18: =Calc1_Engine!C134 | H18: After-Tax Income | I18: =Calc1_Engine!C143
B19: Tax Credits | C19: =-Calc1_Engine!C116
B20: Estimated Total Tax | C20: =Calc1_Engine!C137
B21: Effective Tax Rate | C21: =Calc1_Engine!C138
B22: Marginal Federal Tax Rate | C22: =Calc1_Engine!C139
B23: Marginal State Tax Rate | C23: =Calc1_Engine!C140
B25: Cash-Flow View
B26: Estimated Monthly Tax | C26: =Calc1_Engine!C141
B27: Estimated Quarterly Tax | C27: =Calc1_Engine!C142
B28: Estimated After-Tax Income | C28: =Calc1_Engine!C143
B29: Estimated After-Tax Monthly Income | C29: =Calc1_Engine!C144

Sheet Calc2_Portfolio_Inputs
A1: CALCULATOR 2: PORTFOLIO TAX ESTIMATOR - INPUTS
A2: Enter salary (to establish the marginal bracket) and portfolio income detail. You do not need your full financial picture here.
A4: Household Setup
B5: Filing Status | C5: Married Filing Jointly
B6: Tax Year | C6: 2025
B7: State of Residence | C7: California
B8: State Tax Rate if 'Other (Manual Entry)' Selected | C8: 0.05
B9: Annual Salary / Income - Individual 1 | C9: 150000
B10: Annual Salary / Income - Individual 2 / Spouse | C10: 100000
A12: Interest Income
B13: Treasury Interest (federally taxable; state-exempt) | C13: 0
B14: Corporate Bond Interest | C14: 2000
B15: CD Interest | C15: 1500
B16: Savings Account Interest | C16: 1500
B17: Other Taxable Interest | C17: 0
B18: Tax-Exempt Interest (Municipal Bonds) | C18: 3000
A20: Dividend Income
B21: Qualified Dividends | C21: 8000
B22: Ordinary Dividends | C22: 4000
B23: ETF Distributions (ordinary, non-qualified portion) | C23: 0
A25: Capital Gains & Losses
B26: Short-Term Capital Gains | C26: 3000
B27: Short-Term Capital Losses (enter as positive) | C27: 0
B28: Long-Term Capital Gains | C28: 7000
B29: Mutual Fund Long-Term Capital Gain Distributions | C29: 0
B30: Long-Term Capital Losses (enter as positive) | C30: 2000
B31: Capital-Loss Carryforward (prior years, LT character) | C31: 0
A33: Other Investment Income
B34: REIT Income / Distributions | C34: 0
B35: Partnership / K-1 Investment Income | C35: 0
B36: Rental / Investment Income | C36: 0
B37: Other Taxable Investment Income | C37: 0

Sheet Calc2_Portfolio_Engine
A1: CALCULATOR 2 ENGINE - INCREMENTAL PORTFOLIO TAX CALCULATION
A2: Portfolio tax is computed incrementally: tax WITH the portfolio minus tax on salary ALONE, so gains/dividends are taxed at the bracket they actually fall into - not an average rate.
K3: WORKING LOOKUP TABLES
A4: 1. Baseline Tax on Salary Alone (no portfolio) | K4: Filing Status | L4: ='Calc2_Portfolio_Inputs'!C5
B5: Standard Deduction (selected tax year/status) | C5: =INDEX(Params_Federal!$D$32:$D$41,L9) | K5: Tax Year | L5: ='Calc2_Portfolio_Inputs'!C6
B6: Salary - Individual 1 | C6: ='Calc2_Portfolio_Inputs'!C9 | K6: Federal Key | L6: =L5&"|"&L4
B7: Salary - Individual 2 | C7: ='Calc2_Portfolio_Inputs'!C10 | K7: Fed Bracket Row# | L7: =MATCH(L6,Params_Federal!$C$6:$C$15,0)
B8: Total Salary Income | C8: =(C6+C7) | K8: LTCG Bracket Row# | L8: =MATCH(L6,Params_Federal!$C$19:$C$28,0)
B9: Baseline Taxable Income (salary only) | C9: =MAX(0,C8-C5) | K9: StdDed Row# | L9: =MATCH(L6,Params_Federal!$C$32:$C$41,0)
B10: Baseline Federal Tax (salary only) | C10: =SUMPRODUCT((C9>$L$20:$L$26)*($K$20:$K$26)*(MIN(C9,$M$20:$M$26)-$L$20:$L$26)) | K10: Status Row# (NIIT) | L10: =MATCH(L4,Params_Federal!$A$45:$A$49,0)
K11: Year Row# (Payroll) | L11: =MATCH(L5,Params_Federal!$A$66:$A$67,0)
A12: 2. Portfolio Income Aggregation | K12: State Name | L12: ='Calc2_Portfolio_Inputs'!C7
B13: Total Taxable Interest (Treasury+Corp+CD+Savings+Other) | C13: =('Calc2_Portfolio_Inputs'!C13+'Calc2_Portfolio_Inputs'!C14+'Calc2_Portfolio_Inputs'!C15+'Calc2_Portfolio_Inputs'!C16+'Calc2_Portfolio_Inputs'!C17) | K13: State Code | L13: =INDEX(Params_State!$A$6:$A$37,MATCH(L12,Params_State!$B$6:$B$37,0))
B14: Tax-Exempt Interest (Municipal) | C14: ='Calc2_Portfolio_Inputs'!C18 | K14: State Category | L14: =IF(OR(L4="Married Filing Jointly",L4="Qualifying Surviving Spouse"),"MFJ","Single")
B15: Qualified Dividends | C15: ='Calc2_Portfolio_Inputs'!C21 | K15: State Key | L15: =L13&"|"&L14
B16: Ordinary Dividends + ETF Distributions | C16: =('Calc2_Portfolio_Inputs'!C22+'Calc2_Portfolio_Inputs'!C23) | K16: State Bracket Row# | L16: =MATCH(L15,Params_State!$C$41:$C$104,0)
B17: REIT + K-1 + Rental + Other Investment Income | C17: =('Calc2_Portfolio_Inputs'!C34+'Calc2_Portfolio_Inputs'!C35+'Calc2_Portfolio_Inputs'!C36+'Calc2_Portfolio_Inputs'!C37) | K17: State Master Row# | L17: =MATCH(L13,Params_State!$A$6:$A$37,0)
B18: Ordinary-Taxed Investment Income (Interest + Ord. Div + Other) | C18: =(C13+C16+C17)
K19: Federal Ordinary Brackets
A20: 3. Capital Gain / Loss Netting | K20: =INDEX(Params_Federal!D$6:D$1005,L7) | L20: =INDEX(Params_Federal!E$6:E$1005,L7) | M20: =INDEX(Params_Federal!F$6:F$1005,L7)
B21: Net Short-Term Gain / (Loss) | C21: =('Calc2_Portfolio_Inputs'!C26-'Calc2_Portfolio_Inputs'!C27) | K21: =INDEX(Params_Federal!G$6:G$1005,L7) | L21: =INDEX(Params_Federal!H$6:H$1005,L7) | M21: =INDEX(Params_Federal!I$6:I$1005,L7)
B22: Net Long-Term Gain / (Loss), incl. mutual fund distributions, net of carryforward | C22: =('Calc2_Portfolio_Inputs'!C28+'Calc2_Portfolio_Inputs'!C29-'Calc2_Portfolio_Inputs'!C30-'Calc2_Portfolio_Inputs'!C31) | K22: =INDEX(Params_Federal!J$6:J$1005,L7) | L22: =INDEX(Params_Federal!K$6:K$1005,L7) | M22: =INDEX(Params_Federal!L$6:L$1005,L7)
B23: Combined Net Capital Gain / (Loss) | C23: =(C21+C22) | K23: =INDEX(Params_Federal!M$6:M$1005,L7) | L23: =INDEX(Params_Federal!N$6:N$1005,L7) | M23: =INDEX(Params_Federal!O$6:O$1005,L7)
B24: Capital Loss Limit vs. Ordinary Income | C24: =INDEX(Params_Federal!$D$45:$D$49,L10) | K24: =INDEX(Params_Federal!P$6:P$1005,L7) | L24: =INDEX(Params_Federal!Q$6:Q$1005,L7) | M24: =INDEX(Params_Federal!R$6:R$1005,L7)
B25: Ordinary-Taxed Capital Gain / (Loss Deduction, capped) | C25: =IF(C23<=0,MAX(C23,-C24),IF(AND(C21>=0,C22>=0),C21,IF(AND(C21<0,C22>=0),0,IF(AND(C21>=0,C22<0),C23,0)))) | K25: =INDEX(Params_Federal!S$6:S$1005,L7) | L25: =INDEX(Params_Federal!T$6:T$1005,L7) | M25: =INDEX(Params_Federal!U$6:U$1005,L7)
B26: Preferential (LTCG-Rate) Net Capital Gain | C26: =IF(C23<=0,0,IF(AND(C21>=0,C22>=0),C22,IF(AND(C21<0,C22>=0),C23,IF(AND(C21>=0,C22<0),0,0)))) | K26: =INDEX(Params_Federal!V$6:V$1005,L7) | L26: =INDEX(Params_Federal!W$6:W$1005,L7) | M26: =INDEX(Params_Federal!X$6:X$1005,L7)
B27: Capital-Loss Carryforward to Future Years | C27: =IF(C23<=0,C23-MAX(C23,-C24),0)
K28: LTCG / QDI Brackets
A29: 4. Incremental Federal Tax - Stacked on Top of Salary | K29: =INDEX(Params_Federal!D$19:D$1018,L8) | L29: =INDEX(Params_Federal!E$19:E$1018,L8) | M29: =INDEX(Params_Federal!F$19:F$1018,L8)
B30: Taxable Income: Salary + Ordinary Investment Income + Ordinary Capital Gain | C30: =MAX(0,C8+C18+C25-C5) | K30: =INDEX(Params_Federal!G$19:G$1018,L8) | L30: =INDEX(Params_Federal!H$19:H$1018,L8) | M30: =INDEX(Params_Federal!I$19:I$1018,L8)
B31: Federal Tax at Step 1 (Salary + Ordinary Investment Income) | C31: =SUMPRODUCT((C30>$L$20:$L$26)*($K$20:$K$26)*(MIN(C30,$M$20:$M$26)-$L$20:$L$26)) | K31: =INDEX(Params_Federal!J$19:J$1018,L8) | L31: =INDEX(Params_Federal!K$19:K$1018,L8) | M31: =INDEX(Params_Federal!L$19:L$1018,L8)
B32: Tax Attributable to Interest / Ordinary Dividends / Short-Term Gains | C32: =(C31-C10)
B33: Taxable Income: Step 1 + Qualified Dividends | C33: =(C30+C15) | K33: State Brackets
B34: Federal Cap Gains Tax on Qualified Dividends (stacked) | C34: =SUMPRODUCT($K$29:$K$31*(MAX(0,MIN(C33,$M$29:$M$31)-MAX(C30,$L$29:$L$31)))) | K34: =INDEX(Params_State!D$41:D$1040,L16) | L34: =INDEX(Params_State!E$41:E$1040,L16) | M34: =INDEX(Params_State!F$41:F$1040,L16)
B35: Taxable Income: Step 2 + Long-Term Capital Gain | C35: =(C33+C26) | K35: =INDEX(Params_State!G$41:G$1040,L16) | L35: =INDEX(Params_State!H$41:H$1040,L16) | M35: =INDEX(Params_State!I$41:I$1040,L16)
B36: Federal Cap Gains Tax through Step 3 (cumulative, stacked) | C36: =SUMPRODUCT($K$29:$K$31*(MAX(0,MIN(C35,$M$29:$M$31)-MAX(C30,$L$29:$L$31)))) | K36: =INDEX(Params_State!J$41:J$1040,L16) | L36: =INDEX(Params_State!K$41:K$1040,L16) | M36: =INDEX(Params_State!L$41:L$1040,L16)
B37: Tax Attributable to Long-Term Capital Gains | C37: =(C36-C34) | K37: =INDEX(Params_State!M$41:M$1040,L16) | L37: =INDEX(Params_State!N$41:N$1040,L16) | M37: =INDEX(Params_State!O$41:O$1040,L16)
B38: Total Incremental Federal Tax from Portfolio | C38: =(C32+C34+C37) | K38: =INDEX(Params_State!P$41:P$1040,L16) | L38: =INDEX(Params_State!Q$41:Q$1040,L16) | M38: =INDEX(Params_State!R$41:R$1040,L16)
K39: =INDEX(Params_State!S$41:S$1040,L16) | L39: =INDEX(Params_State!T$41:T$1040,L16) | M39: =INDEX(Params_State!U$41:U$1040,L16)
A40: 5. Net Investment Income Tax (NIIT) | K40: =INDEX(Params_State!V$41:V$1040,L16) | L40: =INDEX(Params_State!W$41:W$1040,L16) | M40: =INDEX(Params_State!X$41:X$1040,L16)
...

Sheet Calc2_Portfolio_Results
A1: CALCULATOR 2: PORTFOLIO TAX ESTIMATOR - RESULTS
A2: For planning purposes only - not tax advice. See Assumptions_Disclaimer tab.
B4: Estimated Annual Portfolio Tax | C4: Portfolio Tax Rate | D4: After-Tax Portfolio Income | E4: Marginal Rate on Next $ of Ordinary Portfolio Income
B5: =Calc2_Portfolio_Engine!C60 | C5: =Calc2_Portfolio_Engine!C61 | D5: =Calc2_Portfolio_Engine!C62 | E5: =Calc2_Portfolio_Engine!C63
B7: Portfolio Tax Estimate
B8: Total Portfolio Income | C8: =Calc2_Portfolio_Engine!C56
B9: Qualified Dividends | C9: =Calc2_Portfolio_Engine!C15
B10: Ordinary Dividends (incl. ETF) | C10: =Calc2_Portfolio_Engine!C16
B11: Taxable Interest | C11: =Calc2_Portfolio_Engine!C13
B12: Tax-Exempt Interest (municipal) | C12: =Calc2_Portfolio_Engine!C14
B13: Net Ordinary-Taxed Capital Gain | C13: =Calc2_Portfolio_Engine!C25
B14: Net Long-Term (Preferential) Capital Gain | C14: =Calc2_Portfolio_Engine!C26
B15: Estimated Federal Tax (Interest/Ord.Div./ST Gains + QDI + LTCG) | C15: =Calc2_Portfolio_Engine!C38
B16: Estimated NIIT | C16: =Calc2_Portfolio_Engine!C45
B17: Estimated State Tax | C17: =Calc2_Portfolio_Engine!C53
B18: Estimated Total Portfolio Tax | C18: =Calc2_Portfolio_Engine!C60
B19: Estimated Portfolio Tax Rate | C19: =Calc2_Portfolio_Engine!C61
B20: Estimated After-Tax Portfolio Income | C20: =Calc2_Portfolio_Engine!C62
B22: Tax by Income Type
B23: Tax on Interest / Ordinary Dividends / Short-Term Gains | C23: =Calc2_Portfolio_Engine!C32 | H23: Tax on Interest / Ordinary Dividends / Short-Term Gains | I23: =Calc2_Portfolio_Engine!C32
B24: Tax on Qualified Dividends | C24: =Calc2_Portfolio_Engine!C34 | H24: Tax on Qualified Dividends | I24: =Calc2_Portfolio_Engine!C34
B25: Tax on Long-Term Capital Gains | C25: =Calc2_Portfolio_Engine!C37 | H25: Tax on Long-Term Capital Gains | I25: =Calc2_Portfolio_Engine!C37
B26: Net Investment Income Tax (NIIT) | C26: =Calc2_Portfolio_Engine!C45 | H26: Net Investment Income Tax (NIIT) | I26: =Calc2_Portfolio_Engine!C45
B27: State Tax | C27: =Calc2_Portfolio_Engine!C53 | H27: State Tax | I27: =Calc2_Portfolio_Engine!C53
B29: Taxable Income Room Before Next Ordinary Bracket | C29: =Calc2_Portfolio_Engine!C65
B30: Marginal LTCG/QDI Rate on Next Dollar | C30: =Calc2_Portfolio_Engine!C64
H32: Item | I32: Amount
H33: Total Portfolio Income | I33: =Calc2_Portfolio_Engine!C56
H34: Total Portfolio Tax | I34: =Calc2_Portfolio_Engine!C60
H35: After-Tax Portfolio Income | I35: =Calc2_Portfolio_Engine!C62

Sheet WhatIf_Scenarios
A1: WHAT-IF SCENARIO COMPARISON
A2: Compares Calculator 1's current household tax (Scenario A) against two alternatives you define. State tax impact is approximated using the state's bracket formula applied to the adjusted state taxable income.
C4: Scenario A: Current | D4: Scenario B | E4: Scenario C
B5: Levers (Scenario B / C only - enter deltas)
B6: Additional Ordinary Investment Income (interest/nonqual. div./ST gains) | C6: 0 | D6: 0 | E6: 0
B7: Additional Long-Term Capital Gains Realized | C7: 0 | D7: 0 | E7: 0
B8: Capital Losses Harvested (reduces LT gain) | C8: 0 | D8: 0 | E8: 0
B9: Additional Pre-Tax Retirement Contribution | C9: 0 | D9: 0 | E9: 0
B11: Recalculated Results
B12: New Total Taxable Income | C12: =MAX(0,Calc1_Engine!C69+0+0-0-0) | D12: =MAX(0,Calc1_Engine!C69+D6+D7-D8-D9) | E12: =MAX(0,Calc1_Engine!C69+E6+E7-E8-E9)
B13: New Preferential (LTCG/QDI) Stacked Amount | C13: =MIN(C12,MAX(0,Calc1_Engine!C70+0-0)) | D13: =MIN(D12,MAX(0,Calc1_Engine!C70+D7-D8)) | E13: =MIN(E12,MAX(0,Calc1_Engine!C70+E7-E8))
B14: New Ordinary Taxable Income | C14: =MAX(0,C12-C13) | D14: =MAX(0,D12-D13) | E14: =MAX(0,E12-E13)
B15: New Federal Ordinary Tax | C15: =SUMPRODUCT((C14>Calc1_Engine!$L$25:$L$31)*(Calc1_Engine!$K$25:$K$31)*(MIN(C14,Calc1_Engine!$M$25:$M$31)-Calc1_Engine!$L$25:$L$31)) | D15: =SUMPRODUCT((D14>Calc1_Engine!$L$25:$L$31)*(Calc1_Engine!$K$25:$K$31)*(MIN(D14,Calc1_Engine!$M$25:$M$31)-Calc1_Engine!$L$25:$L$31)) | E15: =SUMPRODUCT((E14>Calc1_Engine!$L$25:$L$31)*(Calc1_Engine!$K$25:$K$31)*(MIN(E14,Calc1_Engine!$M$25:$M$31)-Calc1_Engine!$L$25:$L$31))
B16: New Federal Capital Gains Tax | C16: =SUMPRODUCT(Calc1_Engine!$K$34:$K$36*(MAX(0,MIN(C12,Calc1_Engine!$M$34:$M$36)-MAX(C14,Calc1_Engine!$L$34:$L$36)))) | D16: =SUMPRODUCT(Calc1_Engine!$K$34:$K$36*(MAX(0,MIN(D12,Calc1_Engine!$M$34:$M$36)-MAX(D14,Calc1_Engine!$L$34:$L$36)))) | E16: =SUMPRODUCT(Calc1_Engine!$K$34:$K$36*(MAX(0,MIN(E12,Calc1_Engine!$M$34:$M$36)-MAX(E14,Calc1_Engine!$L$34:$L$36))))
B17: New NIIT | C17: =Calc1_Engine!C81*MIN(MAX(0,Calc1_Engine!C80+0+0-0),MAX(0,Calc1_Engine!C51+0+0-0-0-Calc1_Engine!C79)) | D17: =Calc1_Engine!C81*MIN(MAX(0,Calc1_Engine!C80+D6+D7-D8),MAX(0,Calc1_Engine!C51+D6+D7-D8-D9-Calc1_Engine!C79)) | E17: =Calc1_Engine!C81*MIN(MAX(0,Calc1_Engine!C80+E6+E7-E8),MAX(0,Calc1_Engine!C51+E6+E7-E8-E9-Calc1_Engine!C79))
B18: New State Taxable Income | C18: =MAX(0,Calc1_Engine!C126+0+0-0-0) | D18: =MAX(0,Calc1_Engine!C126+D6+D7-D8-D9) | E18: =MAX(0,Calc1_Engine!C126+E6+E7-E8-E9)
B19: New State Tax | C19: =IF(Calc1_Engine!L16="OTHER",Calc1_Inputs!C8*C18,SUMPRODUCT((C18>Calc1_Engine!$L$39:$L$46)*(Calc1_Engine!$K$39:$K$46)*(MIN(C18,Calc1_Engine!$M$39:$M$46)-Calc1_Engine!$L$39:$L$46))) | D19: =IF(Calc1_Engine!L16="OTHER",Calc1_Inputs!C8*D18,SUMPRODUCT((D18>Calc1_Engine!$L$39:$L$46)*(Calc1_Engine!$K$39:$K$46)*(MIN(D18,Calc1_Engine!$M$39:$M$46)-Calc1_Engine!$L$39:$L$46))) | E19: =IF(Calc1_Engine!L16="OTHER",Calc1_Inputs!C8*E18,SUMPRODUCT((E18>Calc1_Engine!$L$39:$L$46)*(Calc1_Engine!$K$39:$K$46)*(MIN(E18,Calc1_Engine!$M$39:$M$46)-Calc1_Engine!$L$39:$L$46)))
B20: New Total Tax (Federal + NIIT + Payroll + State + Local, net of credits) | C20: =MAX(0,C15+C16+C17+Calc1_Engine!C98+C19+Calc1_Engine!C134-Calc1_Engine!C116) | D20: =MAX(0,D15+D16+D17+Calc1_Engine!C98+D19+Calc1_Engine!C134-Calc1_Engine!C116) | E20: =MAX(0,E15+E16+E17+Calc1_Engine!C98+E19+Calc1_Engine!C134-Calc1_Engine!C116)
B21: New Effective Tax Rate | C21: =IFERROR(C20/Calc1_Engine!C44,0) | D21: =IFERROR(D20/Calc1_Engine!C44,0) | E21: =IFERROR(E20/Calc1_Engine!C44,0)
B22: New After-Tax Income | C22: =(Calc1_Engine!C44-C20) | D22: =(Calc1_Engine!C44-D20) | E22: =(Calc1_Engine!C44-E20)
B24: Scenario Comparison Summary
C25: Scenario B | D25: Scenario C
B26: Tax Before (Scenario A) | C26: =$C$20 | D26: =$C$20
B27: Tax After | C27: =D20 | D27: =E20
B28: Estimated Tax Savings | C28: =$C$20-D20 | D28: =$C$20-E20
B29: Change in Effective Tax Rate | C29: =D21-$C$21 | D29: =E21-$C$21
B30: Change in After-Tax Income | C30: =D22-$C$22 | D30: =E22-$C$22

Sheet Tax_Loss_Harvesting
A1: TAX-LOSS HARVESTING ESTIMATOR
A2: Estimates the tax savings from harvesting additional unrealized losses, applying IRC capital-loss limitation and carryforward rules.
K3: WORKING LOOKUP TABLES
A4: Inputs | K4: Key | L4: =C6&"|"&C5
B5: Filing Status | C5: Married Filing Jointly | K5: Fed Row# | L5: =MATCH(L4,Params_Federal!$C$6:$C$15,0)
B6: Tax Year | C6: 2025 | K6: LTCG Row# | L6: =MATCH(L4,Params_Federal!$C$19:$C$28,0)
B7: Ordinary Taxable Income (before this transaction) | C7: 200000 | K7: Status Row# (CapLoss Limit) | L7: =MATCH(C5,Params_Federal!$A$45:$A$49,0)
B8: Realized Short-Term Capital Gains (current year) | C8: 5000
B9: Realized Long-Term Capital Gains (current year) | C9: 20000 | K9: Federal Ordinary Brackets
B10: Realized Losses (current year, already recognized) | C10: 0 | K10: =INDEX(Params_Federal!D$6:D$1005,L5) | L10: =INDEX(Params_Federal!E$6:E$1005,L5) | M10: =INDEX(Params_Federal!F$6:F$1005,L5)
B11: Capital-Loss Carryforward (prior years) | C11: 0 | K11: =INDEX(Params_Federal!G$6:G$1005,L5) | L11: =INDEX(Params_Federal!H$6:H$1005,L5) | M11: =INDEX(Params_Federal!I$6:I$1005,L5)
B12: Unrealized Losses Being Considered for Harvest | C12: 10000 | K12: =INDEX(Params_Federal!J$6:J$1005,L5) | L12: =INDEX(Params_Federal!K$6:K$1005,L5) | M12: =INDEX(Params_Federal!L$6:L$1005,L5)
K13: =INDEX(Params_Federal!M$6:M$1005,L5) | L13: =INDEX(Params_Federal!N$6:N$1005,L5) | M13: =INDEX(Params_Federal!O$6:O$1005,L5)
A14: Netting - Before Harvest | K14: =INDEX(Params_Federal!P$6:P$1005,L5) | L14: =INDEX(Params_Federal!Q$6:Q$1005,L5) | M14: =INDEX(Params_Federal!R$6:R$1005,L5)
B15: Net Long-Term Gain (before harvest) | C15: =(C9-C10-C11) | K15: =INDEX(Params_Federal!S$6:S$1005,L5) | L15: =INDEX(Params_Federal!T$6:T$1005,L5) | M15: =INDEX(Params_Federal!U$6:U$1005,L5)
B16: Combined Net Capital Gain (before harvest) | C16: =(C8+C15) | K16: =INDEX(Params_Federal!V$6:V$1005,L5) | L16: =INDEX(Params_Federal!W$6:W$1005,L5) | M16: =INDEX(Params_Federal!X$6:X$1005,L5)
B17: Capital Loss Limit vs. Ordinary Income | C17: =INDEX(Params_Federal!$D$45:$D$49,L7)
B18: Ordinary-Taxed Capital Gain (before harvest) | C18: =IF(C16<=0,MAX(C16,-C17),IF(AND(C8>=0,C15>=0),C8,IF(AND(C8<0,C15>=0),0,IF(AND(C8>=0,C15<0),C16,0)))) | K18: LTCG Brackets
B19: Preferential Net Capital Gain (before harvest) | C19: =IF(C16<=0,0,IF(AND(C8>=0,C15>=0),C15,IF(AND(C8<0,C15>=0),C16,IF(AND(C8>=0,C15<0),0,0)))) | K19: =INDEX(Params_Federal!D$19:D$1018,L6) | L19: =INDEX(Params_Federal!E$19:E$1018,L6) | M19: =INDEX(Params_Federal!F$19:F$1018,L6)
K20: =INDEX(Params_Federal!G$19:G$1018,L6) | L20: =INDEX(Params_Federal!H$19:H$1018,L6) | M20: =INDEX(Params_Federal!I$19:I$1018,L6)
A21: Netting - After Harvest | K21: =INDEX(Params_Federal!J$19:J$1018,L6) | L21: =INDEX(Params_Federal!K$19:K$1018,L6) | M21: =INDEX(Params_Federal!L$19:L$1018,L6)
B22: Net Long-Term Gain (after harvest) | C22: =(C15-C12)
B23: Combined Net Capital Gain (after harvest) | C23: =(C8+C22)
B24: Ordinary-Taxed Capital Gain (after harvest) | C24: =IF(C23<=0,MAX(C23,-C17),IF(AND(C8>=0,C22>=0),C8,IF(AND(C8<0,C22>=0),0,IF(AND(C8>=0,C22<0),C23,0))))
B25: Preferential Net Capital Gain (after harvest) | C25: =IF(C23<=0,0,IF(AND(C8>=0,C22>=0),C22,IF(AND(C8<0,C22>=0),C23,IF(AND(C8>=0,C22<0),0,0))))
B26: Remaining Capital-Loss Carryforward (after harvest) | C26: =IF(C23<=0,C23-MAX(C23,-C17),0)
A28: Tax Impact
B29: Ordinary Taxable Income Before Harvest | C29: =MAX(0,C7+C18)
B30: Ordinary Taxable Income After Harvest | C30: =MAX(0,C7+C24)
B31: Federal Tax Before Harvest | C31: =SUMPRODUCT((C29>$L$10:$L$16)*($K$10:$K$16)*(MIN(C29,$M$10:$M$16)-$L$10:$L$16))+SUMPRODUCT($K$19:$K$21*(MAX(0,MIN((C29+C19),$M$19:$M$21)-MAX(C29,$L$19:$L$21))))
B32: Federal Tax After Harvest | C32: =SUMPRODUCT((C30>$L$10:$L$16)*($K$10:$K$16)*(MIN(C30,$M$10:$M$16)-$L$10:$L$16))+SUMPRODUCT($K$19:$K$21*(MAX(0,MIN((C30+C25),$M$19:$M$21)-MAX(C30,$L$19:$L$21))))
B33: Estimated Tax Savings from Harvesting | C33: =(C31-C32)
B34: Additional Loss Used Against Ordinary Income This Year | C34: =MIN(C12,MAX(0,C18-C24))

Sheet Retirement_Contribution
A1: ADDITIONAL PRE-TAX RETIREMENT CONTRIBUTION ESTIMATOR
A2: Estimates the federal and state tax savings, and the true after-tax cost, of an additional pre-tax contribution.
K3: WORKING LOOKUP TABLES
A4: Inputs | K4: Fed Key | L4: =C6&"|"&C5
B5: Filing Status | C5: Married Filing Jointly | K5: Fed Row# | L5: =MATCH(L4,Params_Federal!$C$6:$C$15,0)
B6: Tax Year | C6: 2025 | K6: LTCG Row# | L6: =MATCH(L4,Params_Federal!$C$19:$C$28,0)
B7: State of Residence | C7: California | K7: State Code | L7: =INDEX(Params_State!$A$6:$A$37,MATCH(C7,Params_State!$B$6:$B$37,0))
B8: State Tax Rate if 'Other (Manual Entry)' Selected | C8: 0.05 | K8: State Category | L8: =IF(OR(C5="Married Filing Jointly",C5="Qualifying Surviving Spouse"),"MFJ","Single")
B9: Contribution Reduces State Taxable Income? | C9: Y | K9: State Key | L9: =L7&"|"&L8
B10: Current Ordinary Taxable Income (before this contribution) | C10: 250000 | K10: State Bracket Row# | L10: =MATCH(L9,Params_State!$C$41:$C$104,0)
B11: Preferential Income Already Stacked on Top (QDI/LTCG, if any) | C11: 0
B12: Proposed Additional Pre-Tax Contribution | C12: 10000 | K12: Federal Ordinary Brackets
K13: =INDEX(Params_Federal!D$6:D$1005,L5) | L13: =INDEX(Params_Federal!E$6:E$1005,L5) | M13: =INDEX(Params_Federal!F$6:F$1005,L5)
A14: Results | K14: =INDEX(Params_Federal!G$6:G$1005,L5) | L14: =INDEX(Params_Federal!H$6:H$1005,L5) | M14: =INDEX(Params_Federal!I$6:I$1005,L5)
B15: Taxable Income After Contribution | C15: =MAX(0,C10-C12) | K15: =INDEX(Params_Federal!J$6:J$1005,L5) | L15: =INDEX(Params_Federal!K$6:K$1005,L5) | M15: =INDEX(Params_Federal!L$6:L$1005,L5)
B16: Federal Tax Before (ordinary + any stacked preferential income) | C16: =SUMPRODUCT((C10>$L$13:$L$19)*($K$13:$K$19)*(MIN(C10,$M$13:$M$19)-$L$13:$L$19))+SUMPRODUCT($K$22:$K$24*(MAX(0,MIN((C10+C11),$M$22:$M$24)-MAX(C10,$L$22:$L$24)))) | K16: =INDEX(Params_Federal!M$6:M$1005,L5) | L16: =INDEX(Params_Federal!N$6:N$1005,L5) | M16: =INDEX(Params_Federal!O$6:O$1005,L5)
B17: Federal Tax After | C17: =SUMPRODUCT((C15>$L$13:$L$19)*($K$13:$K$19)*(MIN(C15,$M$13:$M$19)-$L$13:$L$19))+SUMPRODUCT($K$22:$K$24*(MAX(0,MIN((C15+C11),$M$22:$M$24)-MAX(C15,$L$22:$L$24)))) | K17: =INDEX(Params_Federal!P$6:P$1005,L5) | L17: =INDEX(Params_Federal!Q$6:Q$1005,L5) | M17: =INDEX(Params_Federal!R$6:R$1005,L5)
B18: Federal Tax Savings | C18: =(C16-C17) | K18: =INDEX(Params_Federal!S$6:S$1005,L5) | L18: =INDEX(Params_Federal!T$6:T$1005,L5) | M18: =INDEX(Params_Federal!U$6:U$1005,L5)
B19: State Tax Before | C19: =IF(L7="OTHER",C8*C10,SUMPRODUCT((C10>$L$27:$L$34)*($K$27:$K$34)*(MIN(C10,$M$27:$M$34)-$L$27:$L$34))) | K19: =INDEX(Params_Federal!V$6:V$1005,L5) | L19: =INDEX(Params_Federal!W$6:W$1005,L5) | M19: =INDEX(Params_Federal!X$6:X$1005,L5)
B20: State Tax After (if contribution reduces state taxable income) | C20: =IF(C9="N",C19,IF(L7="OTHER",C8*C15,SUMPRODUCT((C15>$L$27:$L$34)*($K$27:$K$34)*(MIN(C15,$M$27:$M$34)-$L$27:$L$34))))
B21: State Tax Savings | C21: =(C19-C20) | K21: LTCG Brackets
B22: Total Estimated Tax Savings | C22: =(C18+C21) | K22: =INDEX(Params_Federal!D$19:D$1018,L6) | L22: =INDEX(Params_Federal!E$19:E$1018,L6) | M22: =INDEX(Params_Federal!F$19:F$1018,L6)
B23: Estimated After-Tax Cost of the Contribution | C23: =(C12-C22) | K23: =INDEX(Params_Federal!G$19:G$1018,L6) | L23: =INDEX(Params_Federal!H$19:H$1018,L6) | M23: =INDEX(Params_Federal!I$19:I$1018,L6)
B24: Effective Savings Rate on the Contribution | C24: =IFERROR(C22/C12,0) | K24: =INDEX(Params_Federal!J$19:J$1018,L6) | L24: =INDEX(Params_Federal!K$19:K$1018,L6) | M24: =INDEX(Params_Federal!L$19:L$1018,L6)
K26: State Brackets
K27: =INDEX(Params_State!D$41:D$1040,L10) | L27: =INDEX(Params_State!E$41:E$1040,L10) | M27: =INDEX(Params_State!F$41:F$1040,L10)
K28: =INDEX(Params_State!G$41:G$1040,L10) | L28: =INDEX(Params_State!H$41:H$1040,L10) | M28: =INDEX(Params_State!I$41:I$1040,L10)
K29: =INDEX(Params_State!J$41:J$1040,L10) | L29: =INDEX(Params_State!K$41:K$1040,L10) | M29: =INDEX(Params_State!L$41:L$1040,L10)
K30: =INDEX(Params_State!M$41:M$1040,L10) | L30: =INDEX(Params_State!N$41:N$1040,L10) | M30: =INDEX(Params_State!O$41:O$1040,L10)
K31: =INDEX(Params_State!P$41:P$1040,L10) | L31: =INDEX(Params_State!Q$41:Q$1040,L10) | M31: =INDEX(Params_State!R$41:R$1040,L10)
K32: =INDEX(Params_State!S$41:S$1040,L10) | L32: =INDEX(Params_State!T$41:T$1040,L10) | M32: =INDEX(Params_State!U$41:U$1040,L10)
K33: =INDEX(Params_State!V$41:V$1040,L10) | L33: =INDEX(Params_State!W$41:W$1040,L10) | M33: =INDEX(Params_State!X$41:X$1040,L10)
K34: =INDEX(Params_State!Y$41:Y$1040,L10) | L34: =INDEX(Params_State!Z$41:Z$1040,L10) | M34: =INDEX(Params_State!AA$41:AA$1040,L10)

Sheet Assumptions_Disclaimer
A1: DISCLAIMER & METHODOLOGY / ASSUMPTIONS
A3: Tax estimates are for educational and financial-planning purposes only. Actual tax liability may differ based on individual circumstances, deductions, credits, tax elections, state/local rules, and other factors. This calculator does not provide tax, legal, or accounting advice. Consult a qualified tax professional regarding your individual situation.
A9: How Figures Are Sourced
A10: • Tax Year Coverage: 2024 and 2025. All bracket, deduction, credit, and limit figures live on the Params_Federal, Params_State, and Params_Local tabs (not hardcoded in formulas), so the workbook can be extended to future tax years by adding rows to those tables.
A11: • Federal ordinary brackets, standard deductions, and long-term capital gains / qualified dividend brackets reflect published IRS inflation-adjusted figures for 2024 and 2025.
A12: • The Net Investment Income Tax (3.8%) and Additional Medicare Tax (0.9%) thresholds are fixed by statute and have not been inflation-adjusted since enactment (2013).
A13: • The SALT itemized deduction cap reflects the $10,000 TCJA-era cap for 2024 and the higher, phased cap enacted for 2025 and later years; the 2025+ figure does not model the high-income phase-down and should be verified for clients above roughly $500,000 of income.
A14: • Modified AGI (MAGI) for NIIT purposes is approximated as AGI (no addback for excluded foreign earned income, which is uncommon for most clients).
A15: • Additional Medicare Tax is modeled as the total-liability version (0.9% on combined wages and self-employment income above the filing-status threshold), not the separate per-employer withholding mechanics of IRS Form 8959.
A17: Capital Gains, Losses & Netting
A18: • Short-term and long-term gains/losses are netted using standard IRC Sec. 1211/1222 ordering: a net short-term loss first offsets net long-term gain (and vice versa) before any loss is allowed against ordinary income, capped at $3,000 ($1,500 if Married Filing Separately) with the remainder carried forward indefinitely.
A19: • Prior-year capital-loss carryforwards are assumed to retain long-term character.
... A47: • All inputs marked in gold/blue are user-editable. All parameter tables (Params_Federal, Params_State, Params_Local) are user-editable and drive every calculation - update them as tax law changes.
